<?xml version='1.0' encoding='utf-8'?>
<mujoco model="adam_u">
  <option timestep="0.001" integrator="implicitfast" iterations="50" solver="Newton"/>

  <default>
    <default class="visual">
      <geom group="2" type="mesh" contype="0" conaffinity="0" density="0" />
    </default>
    <default class="collision">
      <geom group="3" type="mesh" contype="1" conaffinity="2"
            solref="0.02 1" solimp="0.9 0.95 0.001" margin="0.001"/>
    </default>
  </default>
  <compiler angle="radian" meshdir="assets/" />
  <asset>
    <material name="black" specular="0.0" shininess="0.25" rgba="0.2 0.2 0.2 1.000000" />
    <material name="sliver" specular="0.0" shininess="0.25" rgba="0.7 0.7 0.7 1.000000" />
    <mesh name="lifting_Columns_0" file="lifting_Columns_0.obj" />
    <mesh name="lifting_Columns_1" file="lifting_Columns_1.obj" />
    <mesh name="waistRoll_0" file="waistRoll_0.obj" />
    <mesh name="waistRoll_1" file="waistRoll_1.obj" />
    <mesh name="waistPitch_0" file="waistPitch_0.obj" />
    <mesh name="waistPitch_1" file="waistPitch_1.obj" />
    <mesh name="torso_0" file="torso_0.obj" />
    <mesh name="torso_1" file="torso_1.obj" />
    <mesh name="shoulderPitchLeft" file="shoulderPitchLeft.obj" />
    <mesh name="shoulderRollLeft_0" file="shoulderRollLeft_0.obj" />
    <mesh name="shoulderRollLeft_1" file="shoulderRollLeft_1.obj" />
    <mesh name="shoulderYawLeft_0" file="shoulderYawLeft_0.obj" />
    <mesh name="shoulderYawLeft_1" file="shoulderYawLeft_1.obj" />
    <mesh name="elbowLeft_0" file="elbowLeft_0.obj" />
    <mesh name="elbowLeft_1" file="elbowLeft_1.obj" />
    <mesh name="wristYawLeft_0" file="wristYawLeft_0.obj" />
    <mesh name="wristYawLeft_1" file="wristYawLeft_1.obj" />
    <mesh name="wristPitchLeft" file="wristPitchLeft.obj" />
    <mesh name="wristRollLeft_0" file="wristRollLeft_0.obj" />
    <mesh name="wristRollLeft_1" file="wristRollLeft_1.obj" />
    <mesh name="L_thumb_proximal_base" file="L_thumb_proximal_base.obj" />
    <mesh name="L_thumb_proximal_0" file="L_thumb_proximal_0.obj" />
    <mesh name="L_thumb_proximal_1" file="L_thumb_proximal_1.obj" />
    <mesh name="L_thumb_intermediate" file="L_thumb_intermediate.obj" />
    <mesh name="L_thumb_distal_0" file="L_thumb_distal_0.obj" />
    <mesh name="L_thumb_distal_1" file="L_thumb_distal_1.obj" />
    <mesh name="L_index_proximal_0" file="L_index_proximal_0.obj" />
    <mesh name="L_index_proximal_1" file="L_index_proximal_1.obj" />
    <mesh name="L_index_distal_0" file="L_index_distal_0.obj" />
    <mesh name="L_index_distal_1" file="L_index_distal_1.obj" />
    <mesh name="L_middle_proximal_0" file="L_middle_proximal_0.obj" />
    <mesh name="L_middle_proximal_1" file="L_middle_proximal_1.obj" />
    <mesh name="L_middle_distal_0" file="L_middle_distal_0.obj" />
    <mesh name="L_middle_distal_1" file="L_middle_distal_1.obj" />
    <mesh name="L_ring_proximal_0" file="L_ring_proximal_0.obj" />
    <mesh name="L_ring_proximal_1" file="L_ring_proximal_1.obj" />
    <mesh name="L_ring_distal_0" file="L_ring_distal_0.obj" />
    <mesh name="L_ring_distal_1" file="L_ring_distal_1.obj" />
    <mesh name="L_pinky_proximal_0" file="L_pinky_proximal_0.obj" />
    <mesh name="L_pinky_proximal_1" file="L_pinky_proximal_1.obj" />
    <mesh name="L_pinky_distal_0" file="L_pinky_distal_0.obj" />
    <mesh name="L_pinky_distal_1" file="L_pinky_distal_1.obj" />
    <mesh name="shoulderPitchRight" file="shoulderPitchRight.obj" />
    <mesh name="shoulderRollRight_0" file="shoulderRollRight_0.obj" />
    <mesh name="shoulderRollRight_1" file="shoulderRollRight_1.obj" />
    <mesh name="shoulderYawRight_0" file="shoulderYawRight_0.obj" />
    <mesh name="shoulderYawRight_1" file="shoulderYawRight_1.obj" />
    <mesh name="elbowRight_0" file="elbowRight_0.obj" />
    <mesh name="elbowRight_1" file="elbowRight_1.obj" />
    <mesh name="wristYawRight_0" file="wristYawRight_0.obj" />
    <mesh name="wristYawRight_1" file="wristYawRight_1.obj" />
    <mesh name="wristPitchRight" file="wristPitchRight.obj" />
    <mesh name="wristRollRight_0" file="wristRollRight_0.obj" />
    <mesh name="wristRollRight_1" file="wristRollRight_1.obj" />
    <mesh name="R_thumb_proximal_base" file="R_thumb_proximal_base.obj" />
    <mesh name="R_thumb_proximal_0" file="R_thumb_proximal_0.obj" />
    <mesh name="R_thumb_proximal_1" file="R_thumb_proximal_1.obj" />
    <mesh name="R_thumb_intermediate" file="R_thumb_intermediate.obj" />
    <mesh name="R_thumb_distal_0" file="R_thumb_distal_0.obj" />
    <mesh name="R_thumb_distal_1" file="R_thumb_distal_1.obj" />
    <mesh name="R_index_proximal_0" file="R_index_proximal_0.obj" />
    <mesh name="R_index_proximal_1" file="R_index_proximal_1.obj" />
    <mesh name="R_index_distal_0" file="R_index_distal_0.obj" />
    <mesh name="R_index_distal_1" file="R_index_distal_1.obj" />
    <mesh name="R_middle_proximal_0" file="R_middle_proximal_0.obj" />
    <mesh name="R_middle_proximal_1" file="R_middle_proximal_1.obj" />
    <mesh name="R_middle_distal_0" file="R_middle_distal_0.obj" />
    <mesh name="R_middle_distal_1" file="R_middle_distal_1.obj" />
    <mesh name="R_ring_proximal_0" file="R_ring_proximal_0.obj" />
    <mesh name="R_ring_proximal_1" file="R_ring_proximal_1.obj" />
    <mesh name="R_ring_distal_0" file="R_ring_distal_0.obj" />
    <mesh name="R_ring_distal_1" file="R_ring_distal_1.obj" />
    <mesh name="R_pinky_proximal_0" file="R_pinky_proximal_0.obj" />
    <mesh name="R_pinky_proximal_1" file="R_pinky_proximal_1.obj" />
    <mesh name="R_pinky_distal_0" file="R_pinky_distal_0.obj" />
    <mesh name="R_pinky_distal_1" file="R_pinky_distal_1.obj" />
    <mesh name="neckYaw" file="neckYaw.obj" />
    <mesh name="neckPitch" file="neckPitch.obj" />
  </asset>
  <worldbody>
    <body name="lifting_Columns" pos="0 0 1.05">
      <inertial pos="9.03635e-05 -3.16723e-05 -0.722725" quat="0.499642 0.499654 -0.50034 0.500364" mass="16.1205" diaginertia="0.720003 0.582931 0.351926" />
      <geom mesh="lifting_Columns_0" material="sliver" class="visual" />
      <geom mesh="lifting_Columns_1" material="black" class="visual" />
      <geom mesh="lifting_Columns_0" class="collision" />
      <geom mesh="lifting_Columns_1" class="collision" />
      <body name="waistRoll" pos="0 0 0.0767">
        <inertial pos="0.00093826 0.00093832 0.0399999" quat="0.383833 0.0123801 -0.00511148 0.923305" mass="2.36268" diaginertia="0.00543471 0.00542871 0.00184736" />
          <joint name="waistRoll" pos="0 0 0" axis="1 0 0" range="-0.279 0.279" actuatorfrcrange="-110 110" damping="150" armature="1.0"/>
        <geom mesh="waistRoll_0" material="black" class="visual" />
        <geom mesh="waistRoll_1" material="sliver" class="visual" />
        <geom mesh="waistRoll_0" class="collision" />
        <geom mesh="waistRoll_1" class="collision" />
        <body name="waistPitch" pos="0 0 0.08">
          <inertial pos="-8.401e-05 0.00189362 0.0254832" quat="0.516813 0.52977 -0.475496 0.475554" mass="0.563538" diaginertia="0.00155964 0.00151442 0.000672501" />
          <joint name="waistPitch" pos="0 0 0" axis="0 1 0" range="-0.663 1.361" actuatorfrcrange="-110 110" damping="60" armature="0.5"/>
          <geom mesh="waistPitch_0" material="sliver" class="visual" />
          <geom mesh="waistPitch_1" material="black" class="visual" />
          <geom mesh="waistPitch_0" class="collision" />
          <geom mesh="waistPitch_1" class="collision" />
          <body name="torso" pos="0 0.0005 0.053">
            <inertial pos="-0.00189583 0.00055253 0.163317" quat="0.999349 -0.00096284 0.0357386 -0.00492242" mass="12.2299" diaginertia="0.117556 0.0821464 0.0642412" />
            <joint name="waistYaw" pos="0 0 0" axis="0 0 1" range="-0.829 0.829" actuatorfrcrange="-110 110" damping="60" armature="0.5"/>
            <geom mesh="torso_0" material="black" class="visual" />
            <geom mesh="torso_1" material="sliver" class="visual" />
            <geom mesh="torso_0" class="collision" />
            <geom mesh="torso_1" class="collision" />
            <body name="shoulderPitchLeft" gravcomp="1" pos="0 0.16049 0.25755" quat="0.984807 0.17365 0 0">
              <inertial pos="-0.00066946 0.0263972 0" quat="-0.0066135 0.707076 0.0066135 0.707076" mass="0.216536" diaginertia="0.0003696 0.000307242 0.000186398" />
              <joint name="shoulderPitch_Left" pos="0 0 0" axis="0 1 0" range="-3.613 2.042" actuatorfrcrange="-65 65" damping="8" armature="0.05"/>
              <geom material="sliver" mesh="shoulderPitchLeft" class="visual" />
              <geom mesh="shoulderPitchLeft" class="collision" />
              <body name="shoulderRollLeft" gravcomp="1" pos="0.0335 0.0435 0" quat="0.984807 -0.17365 0 0">
                <inertial pos="-0.0333022 0.00736791 -0.00952035" quat="0.870134 -0.307111 0.128171 0.363486" mass="0.746227" diaginertia="0.000815538 0.00078791 0.000372512" />
                <joint name="shoulderRoll_Left" pos="0 0 0" axis="1 0 0" range="-0.628 2.793" actuatorfrcrange="-65 65" damping="8" armature="0.05"/>
                <geom mesh="shoulderRollLeft_0" material="sliver" class="visual" />
                <geom mesh="shoulderRollLeft_1" material="black" class="visual" />
                <geom mesh="shoulderRollLeft_0" class="collision" />
                <geom mesh="shoulderRollLeft_1" class="collision" />
                <body name="shoulderYawLeft" gravcomp="1" pos="-0.0335 0.034 -0.0585">
                  <inertial pos="-0.00062397 -0.00062667 -0.0812219" quat="0.999905 0.0103613 -0.00814723 0.00405324" mass="0.765739" diaginertia="0.00351373 0.00340393 0.000461796" />
                  <joint name="shoulderYaw_Left" pos="0 0 0" axis="0 0 1" range="-2.583 2.583" actuatorfrcrange="-65 65" damping="8" armature="0.05"/>
                  <geom mesh="shoulderYawLeft_0" material="sliver" class="visual" />
                  <geom mesh="shoulderYawLeft_1" material="black" class="visual" />
                  <geom mesh="shoulderYawLeft_0" class="collision" />
                  <geom mesh="shoulderYawLeft_1" class="collision" />
                  <body name="elbowLeft" gravcomp="1" pos="0 -0.0285 -0.20415">
                    <inertial pos="-0.0136686 0.0291439 -0.0235134" quat="0.873222 -0.101775 -0.232585 0.415968" mass="0.877615" diaginertia="0.00100437 0.000975645 0.000422992" />
                    <joint name="elbow_Left" pos="0 0 0" axis="0 1 0" range="-2.496 0.209" actuatorfrcrange="-30 30" damping="5" armature="0.05"/>
                    <geom mesh="elbowLeft_0" material="black" class="visual" />
                    <geom mesh="elbowLeft_1" material="sliver" class="visual" />
                    <geom mesh="elbowLeft_0" class="collision" />
                    <geom mesh="elbowLeft_1" class="collision" />
                    <body name="wristYawLeft" gravcomp="1" pos="-0.025 0.0285 -0.0729">
                      <inertial pos="-0.00204137 0.00010627 -0.0921678" quat="0.999621 -0.00660845 -0.00776879 -0.0255601" mass="0.955879" diaginertia="0.002562 0.00250145 0.000550223" />
                      <joint name="wristYaw_Left" pos="0 0 0" axis="0 0 1" range="-2.67 2.67" actuatorfrcrange="-6.4 6.4" damping="2" armature="0.02"/>
                      <geom mesh="wristYawLeft_0" material="black" class="visual" />
                      <geom mesh="wristYawLeft_1" material="sliver" class="visual" />
                      <geom mesh="wristYawLeft_0" class="collision" />
                      <geom mesh="wristYawLeft_1" class="collision" />
                      
                      <body name="wristPitchLeft" gravcomp="1" pos="0 0 -0.2017">
                        <inertial pos="-0.00017582 0.00166098 -2.773e-05" quat="0.498275 0.501712 -0.500227 0.499779" mass="0.119635" diaginertia="3.97702e-05 3.35901e-05 2.68997e-05" />
                        <joint name="wristPitch_Left" pos="0 0 0" axis="0 1 0" range="-0.96 0.96" actuatorfrcrange="-6.4 6.4" damping="2" armature="0.02"/>
                        <geom material="sliver" mesh="wristPitchLeft" class="visual" />
                        <geom mesh="wristPitchLeft" class="collision" />
                        <body name="wristRollLeft" gravcomp="1">
                          <inertial pos="-0.00027229 0.00864497 -0.0662702" quat="0.743139 -0.0248702 0.0370789 0.667646" mass="0.357497" diaginertia="0.000432717 0.000318933 0.0001829" />
                          <joint name="wristRoll_Left" pos="0 0 0" axis="1 0 0" range="-0.96 0.96" actuatorfrcrange="-6.4 6.4" damping="2" armature="0.02"/>
                          <geom mesh="wristRollLeft_0" material="black" class="visual" />
                          <geom mesh="wristRollLeft_1" material="sliver" class="visual" />
                          <geom mesh="wristRollLeft_0" class="collision" />
                          <geom mesh="wristRollLeft_1" class="collision" />
                          <site name="left_palm_fts" pos="0 0 -0.1" euler= "0.0 0 3.14159" size="0.01" rgba="1 0 0 1" group="3"/>
                       <body name="L_thumb_proximal_base" gravcomp="1" pos="0.0245 -0.01 -0.047">
                            <inertial pos="0.00431634 0.00026726 -0.00141885" quat="0.402129 0.420407 0.428718 0.691196" mass="0.0089319" diaginertia="5.80786e-07 4.69278e-07 2.69935e-07" />
                            <joint name="L_thumb_MCP_joint1" pos="0 0 0" axis="0 0 -1" range="0 1.1" actuatorfrcrange="-1 1" damping="0.1" armature="0.005"/>
                            <geom material="sliver" mesh="L_thumb_proximal_base" class="visual" />
                            <geom mesh="L_thumb_proximal_base" class="collision" />
                            <body name="L_thumb_proximal" gravcomp="1" pos="0.011954 -0.0010497 0" quat="0.999041 0 0 -0.0437785">
                              <inertial pos="0.0236969 0 -0.0146724" quat="0.655148 0.266048 0.266048 0.655148" mass="0.0615843" diaginertia="2.013e-05 1.73022e-05 5.79777e-06" />
                              <joint name="L_thumb_MCP_joint2" pos="0 0 0" axis="0 1 0" range="0 0.5" actuatorfrcrange="-1 1" damping="0.1" armature="0.005"/>
                              <geom mesh="L_thumb_proximal_0" material="sliver" class="visual" />
                              <geom mesh="L_thumb_proximal_1" material="black" class="visual" />
                              <geom mesh="L_thumb_proximal_0" class="collision" />
                              <geom mesh="L_thumb_proximal_1" class="collision" />
                              <body name="L_thumb_intermediate" gravcomp="1" pos="0.044289 0 -0.037663">
                                <inertial pos="0.00973134 0 -0.00266466" quat="0.681637 0.188072 0.188072 0.681637" mass="0.0153834" diaginertia="1.72e-06 1.65294e-06 7.67055e-07" />
                                <joint name="L_thumb_PIP_joint" pos="0 0 0" axis="0 1 0" range="0 1" actuatorfrcrange="-1 1" damping="0.1" armature="0.005"/>
                                <geom material="sliver" mesh="L_thumb_intermediate" class="visual" />
                                <geom mesh="L_thumb_intermediate" class="collision" />
                                <body name="L_thumb_distal" gravcomp="1" pos="0.016468 0 -0.015461">
                                  <inertial pos="0.00714221 -1.54e-06 -0.00689404" quat="0.967006 0 0.254755 0" mass="0.0104374" diaginertia="8.73238e-07 8.6e-07 4.06762e-07" />
                                  <joint name="L_thumb_DIP_joint" pos="0 0 0" axis="0 1 0" range="0 1.2" actuatorfrcrange="-1 1" damping="0.1" armature="0.005"/>
                                  <geom mesh="L_thumb_distal_0" material="black" class="visual" />
                                  <geom mesh="L_thumb_distal_1" material="sliver" class="visual" />
                                  <geom mesh="L_thumb_distal_0" class="collision" />
                                  <geom mesh="L_thumb_distal_1" class="collision" />
                                  <site name="site_L_thumb_pad" pos="0 0 -0.01" size="0.004 0.001 0.004" euler="0 0 1.57" type="box" rgba="1 0 0 0.5" group="4"/>
                                </body>
                              </body>
                            </body>
                          </body>
                          <body name="L_index_proximal" gravcomp="1" pos="0.026942 0.0095 -0.11498" quat="0.999657 0 -0.026177 0">
                            <inertial pos="0 0.00199817 -0.0131171" quat="0.707089 0.00501356 -0.00501356 0.707089" mass="0.0145411" diaginertia="1.95028e-06 1.95e-06 5.39716e-07" />
                            <joint name="L_index_MCP_joint" pos="0 0 0" axis="-1 0 0" range="0 1.7" actuatorfrcrange="-1 1" damping="0.1" armature="0.005"/>
                            <geom mesh="L_index_proximal_0" material="sliver" class="visual" />
                            <geom mesh="L_index_proximal_1" material="black" class="visual" />
                            <geom mesh="L_index_proximal_0" class="collision" />
                            <geom mesh="L_index_proximal_1" class="collision" />
                            <body name="L_index_distal" gravcomp="1" pos="0 -0.0011127 -0.031981">
                              <inertial pos="0 0.00168954 -0.0153694" quat="0.996466 0.0839918 0 0" mass="0.00905901" diaginertia="1.73e-06 1.72245e-06 2.07554e-07" />
                              <joint name="L_index_DIP_joint" pos="0 0 0" axis="-1 0 0" range="0 1.6" actuatorfrcrange="-1 1" damping="0.1" armature="0.005"/>
                              <geom mesh="L_index_distal_0" material="black" class="visual" />
                              <geom mesh="L_index_distal_1" material="sliver" class="visual" />
                              <geom mesh="L_index_distal_0" class="collision" />
                              <geom mesh="L_index_distal_1" class="collision" />
                              <site name="site_L_index_pad" pos="0 -0.005 -0.035" size="0.004 0.001 0.004" euler="0 0 3.1415" type="box" rgba="1 0 0 0.5" group="4"/>
                            </body>
                          </body>
                          <body name="L_middle_proximal" gravcomp="1" pos="0.008 0.0145 -0.128">
                            <inertial pos="0 0.00115546 -0.0133419" quat="0.999362 0.0357184 0 0" mass="0.013131" diaginertia="1.94e-06 1.93716e-06 5.32843e-07" />
                            <joint name="L_middle_MCP_joint" pos="0 0 0" axis="-1 0 0" range="0 1.7" actuatorfrcrange="-1 1" damping="0.1" armature="0.005"/>
                            <geom mesh="L_middle_proximal_0" material="sliver" class="visual" />
                            <geom mesh="L_middle_proximal_1" material="black" class="visual" />
                            <geom mesh="L_middle_proximal_0" class="collision" />
                            <geom mesh="L_middle_proximal_1" class="collision" />
                            <body name="L_middle_distal" gravcomp="1" pos="0 -0.0029374 -0.031865">
                              <inertial pos="0 -3.933e-05 -0.0154619" quat="0.990386 0.138332 0 0" mass="0.00905901" diaginertia="1.73e-06 1.72396e-06 2.06037e-07" />
                              <joint name="L_middle_DIP_joint" pos="0 0 0" axis="-1 0 0" range="0 1.6" actuatorfrcrange="-1 1" damping="0.1" armature="0.005"/>
                              <geom mesh="L_middle_distal_0" material="black" class="visual" />
                              <geom mesh="L_middle_distal_1" material="sliver" class="visual" />
                              <geom mesh="L_middle_distal_0" class="collision" />
                              <geom mesh="L_middle_distal_1" class="collision" />
                              <site name="site_L_middle_pad" pos="0 -0.005 -0.037" size="0.004 0.001 0.004" euler="0 0 3.1415" type="box" rgba="1 0 0 0.5" group="4"/>
                            </body>
                          </body>
                          <body name="L_ring_proximal" gravcomp="1" pos="-0.010942 0.0095 -0.11998" quat="0.999657 0 0.026177 0">
                            <inertial pos="-3.95e-06 0.00199338 -0.0131311" quat="0.707089 0.00501356 -0.00501356 0.707089" mass="0.0145411" diaginertia="1.95028e-06 1.95e-06 5.39716e-07" />
                            <joint name="L_ring_MCP_joint" pos="0 0 0" axis="-1 0 0" range="0 1.7" actuatorfrcrange="-1 1" damping="0.1" armature="0.005"/>
                            <geom mesh="L_ring_proximal_0" material="black" class="visual" />
                            <geom mesh="L_ring_proximal_1" material="sliver" class="visual" />
                            <geom mesh="L_ring_proximal_0" class="collision" />
                            <geom mesh="L_ring_proximal_1" class="collision" />
                            <body name="L_ring_distal" gravcomp="1" pos="0 -0.0011127 -0.031981">
                              <inertial pos="0 0.00168954 -0.0153694" quat="0.996466 0.0839918 0 0" mass="0.00905901" diaginertia="1.73e-06 1.72245e-06 2.07554e-07" />
                              <joint name="L_ring_DIP_joint" pos="0 0 0" axis="-1 0 0" range="0 1.6" actuatorfrcrange="-1 1" damping="0.1" armature="0.005"/>
                              <geom mesh="L_ring_distal_0" material="black" class="visual" />
                              <geom mesh="L_ring_distal_1" material="sliver" class="visual" />
                              <geom mesh="L_ring_distal_0" class="collision" />
                              <geom mesh="L_ring_distal_1" class="collision" />
                              <site name="site_L_ring_pad" pos="0 -0.006 -0.037" size="0.004 0.001 0.004" euler="0 0 3.1415" type="box" rgba="1 0 0 0.5" group="4"/>
                            </body>
                          </body>
                          <body name="L_pinky_proximal" gravcomp="1" pos="-0.030194 0.0045 -0.11287" quat="0.998135 0 0.061047 0">
                            <inertial pos="0 0.00191043 -0.0132257" quat="0.707089 0.00501356 -0.00501356 0.707089" mass="0.013131" diaginertia="1.94028e-06 1.94e-06 5.29716e-07" />
                            <joint name="L_pinky_MCP_joint" pos="0 0 0" axis="-1 0 0" range="0 1.7" actuatorfrcrange="-1 1" damping="0.1" armature="0.005"/>
                            <geom mesh="L_pinky_proximal_0" material="sliver" class="visual" />
                            <geom mesh="L_pinky_proximal_1" material="black" class="visual" />
                            <geom mesh="L_pinky_proximal_0" class="collision" />
                            <geom mesh="L_pinky_proximal_1" class="collision" />
                            <body name="L_pinky_distal" gravcomp="1" pos="0 -0.0011127 -0.031981">
                              <inertial pos="1.99e-06 0.00260409 -0.0109991" quat="0.997444 0.0714519 0 0" mass="0.00693901" diaginertia="8.6e-07 8.54401e-07 1.45599e-07" />
                              <joint name="L_pinky_DIP_joint" pos="0 0 0" axis="-1 0 0" range="0 1.6" actuatorfrcrange="-1 1" damping="0.1" armature="0.005"/>
                              <geom mesh="L_pinky_distal_0" material="sliver" class="visual" />
                              <geom mesh="L_pinky_distal_1" material="black" class="visual" />
                              <geom mesh="L_pinky_distal_0" class="collision" />
                              <geom mesh="L_pinky_distal_1" class="collision" />
                              <site name="site_L_pinky_pad" pos="0 -0.005 -0.026" size="0.004 0.001 0.004" euler="0 0 3.1415" type="box" rgba="1 0 0 0.5" group="4"/>
                            </body>
                          </body>
                        </body>
                      </body>
                    </body>
                  </body>
                </body>
              </body>
            </body>
            <body name="shoulderPitchRight" gravcomp="1" pos="0 -0.16049 0.25755" quat="0.984807 -0.17365 0 0">
              <inertial pos="-0.00066946 -0.0263972 0" quat="0.0066135 0.707076 -0.0066135 0.707076" mass="0.216536" diaginertia="0.0003696 0.000307242 0.000186398" />
              <joint name="shoulderPitch_Right" pos="0 0 0" axis="0 1 0" range="-3.613 2.042" actuatorfrcrange="-65 65" damping="8" armature="0.05"/>
              <geom material="sliver" mesh="shoulderPitchRight" class="visual" />
              <geom mesh="shoulderPitchRight" class="collision" />
              <body name="shoulderRollRight" gravcomp="1" pos="0.0335 -0.0435 0" quat="0.984807 0.17365 0 0">
                <inertial pos="-0.0332825 -0.00733504 -0.00951107" quat="0.361979 0.127179 -0.307436 0.870793" mass="0.745069" diaginertia="0.000813679 0.000786398 0.000371932" />
                <joint name="shoulderRoll_Right" pos="0 0 0" axis="1 0 0" range="-2.793 0.628" actuatorfrcrange="-65 65" damping="8" armature="0.05"/>
                <geom mesh="shoulderRollRight_0" material="black" class="visual" />
                <geom mesh="shoulderRollRight_1" material="sliver" class="visual" />
                <geom mesh="shoulderRollRight_0" class="collision" />
                <geom mesh="shoulderRollRight_1" class="collision" />
                <body name="shoulderYawRight" gravcomp="1" pos="-0.0335 -0.034 -0.0585">
                  <inertial pos="-0.00062061 0.00064886 -0.0811784" quat="0.999908 -0.0103237 -0.00811901 -0.00333571" mass="0.765306" diaginertia="0.00351104 0.00340126 0.000461643" />
                  <joint name="shoulderYaw_Right" pos="0 0 0" axis="0 0 1" range="-2.583 2.583" actuatorfrcrange="-65 65" damping="8" armature="0.05"/>
                  <geom mesh="shoulderYawRight_0" material="black" class="visual" />
                  <geom mesh="shoulderYawRight_1" material="sliver" class="visual" />
                  <geom mesh="shoulderYawRight_0" class="collision" />
                  <geom mesh="shoulderYawRight_1" class="collision" />
                  <body name="elbowRight" gravcomp="1" pos="0 0.0285 -0.20415">
                    <inertial pos="-0.0136858 -0.0291425 -0.0235137" quat="0.415844 -0.232443 -0.101494 0.873352" mass="0.877615" diaginertia="0.00100372 0.000975597 0.000422847" />
                    <joint name="elbow_Right" pos="0 0 0" axis="0 1 0" range="-2.496 0.209" actuatorfrcrange="-30 30" damping="5" armature="0.05"/>
                    <geom mesh="elbowRight_0" material="sliver" class="visual" />
                    <geom mesh="elbowRight_1" material="black" class="visual" />
                    <geom mesh="elbowRight_0" class="collision" />
                    <geom mesh="elbowRight_1" class="collision" />
                    <body name="wristYawRight" gravcomp="1" pos="-0.025 -0.0285 -0.0729">
                      <inertial pos="-0.00202981 -0.00013146 -0.0921689" quat="0.999613 0.00676608 -0.00779174 0.0258466" mass="0.955878" diaginertia="0.00256155 0.0025005 0.000549744" />
                      <joint name="wristYaw_Right" pos="0 0 0" axis="0 0 1" range="-2.67 2.67" actuatorfrcrange="-6.4 6.4" damping="2" armature="0.02"/>
                      <geom mesh="wristYawRight_0" material="sliver" class="visual" />
                      <geom mesh="wristYawRight_1" material="black" class="visual" />
                      <geom mesh="wristYawRight_0" class="collision" />
                      <geom mesh="wristYawRight_1" class="collision" />
                      <body name="wristPitchRight" gravcomp="1" pos="0 0 -0.2017">
                        <inertial pos="-0.0001758 0.00166098 -2.773e-05" quat="0.498275 0.501712 -0.500227 0.499779" mass="0.119635" diaginertia="3.97702e-05 3.35901e-05 2.68997e-05" />
                        <joint name="wristPitch_Right" pos="0 0 0" axis="0 1 0" range="-0.96 0.96" actuatorfrcrange="-6.4 6.4" damping="2" armature="0.02"/>
                        <geom material="sliver" mesh="wristPitchRight" class="visual" />
                        <geom mesh="wristPitchRight" class="collision" />
                        <body name="wristRollRight" gravcomp="1">
                          <inertial pos="-0.00030616 -0.00861825 -0.0663443" quat="0.666961 0.0378803 -0.0231418 0.743769" mass="0.358155" diaginertia="0.000433212 0.000319556 0.000183031" />
                          <joint name="wristRoll_Right" pos="0 0 0" axis="1 0 0" range="-0.96 0.96" actuatorfrcrange="-6.4 6.4" damping="2" armature="0.02"/>
                          <geom mesh="wristRollRight_0" material="sliver" class="visual" />
                          <geom mesh="wristRollRight_1" material="black" class="visual" />
                          <geom mesh="wristRollRight_0" class="collision" />
                          <geom mesh="wristRollRight_1" class="collision" />
                          <site name="right_palm_fts" pos="0 0 -0.1" euler = "0 0 0" size="0.01" rgba="0 1 0 1" group="3"/>
                           <body name="R_thumb_proximal_base" gravcomp="1" pos="0.0245 0.01 -0.047">
                            <inertial pos="0.00431634 -0.00026726 -0.00141884" quat="0.691196 0.428718 0.420407 0.402129" mass="0.0089319" diaginertia="5.80786e-07 4.69278e-07 2.69935e-07" />
                            <joint name="R_thumb_MCP_joint1" pos="0 0 0" axis="0 0 1" range="0 1.1" actuatorfrcrange="-1 1" damping="0.1" armature="0.005"/>
                            <geom material="sliver" mesh="R_thumb_proximal_base" class="visual" />
                            <geom mesh="R_thumb_proximal_base" class="collision" />
                            <body name="R_thumb_proximal" gravcomp="1" pos="0.011954 0.0010497 0" quat="0.999041 0 0 0.0437785">
                              <inertial pos="0.0236968 0 -0.0146723" quat="0.655148 0.266048 0.266048 0.655148" mass="0.0615843" diaginertia="2.013e-05 1.73022e-05 5.79777e-06" />
                              <joint name="R_thumb_MCP_joint2" pos="0 0 0" axis="0 1 0" range="0 0.5" actuatorfrcrange="-1 1" damping="0.1" armature="0.005"/>
                              <geom mesh="R_thumb_proximal_0" material="black" class="visual" />
                              <geom mesh="R_thumb_proximal_1" material="sliver" class="visual" />
                              <geom mesh="R_thumb_proximal_0" class="collision" />
                              <geom mesh="R_thumb_proximal_1" class="collision" />
                              <body name="R_thumb_intermediate" gravcomp="1" pos="0.044289 0 -0.037663">
                                <inertial pos="0.00973134 0 -0.00266467" quat="0.681637 0.188072 0.188072 0.681637" mass="0.0153834" diaginertia="1.72e-06 1.65294e-06 7.67055e-07" />
                                <joint name="R_thumb_PIP_joint" pos="0 0 0" axis="0 1 0" range="0 1" actuatorfrcrange="-1 1" damping="0.1" armature="0.005"/>
                                <geom material="sliver" mesh="R_thumb_intermediate" class="visual" />
                                <geom mesh="R_thumb_intermediate" class="collision" />
                                <body name="R_thumb_distal" gravcomp="1" pos="0.016468 0 -0.015461">
                                  <inertial pos="0.00714151 1.39e-06 -0.00689413" quat="0.967006 0 0.254755 0" mass="0.0104374" diaginertia="8.73238e-07 8.6e-07 4.06762e-07" />
                                  <joint name="R_thumb_DIP_joint" pos="0 0 0" axis="0 1 0" range="0 1.2" actuatorfrcrange="-1 1" damping="0.1" armature="0.005"/>
                                  <geom mesh="R_thumb_distal_0" material="sliver" class="visual" />
                                  <geom mesh="R_thumb_distal_1" material="black" class="visual" />
                                  <geom mesh="R_thumb_distal_0" class="collision" />
                                  <geom mesh="R_thumb_distal_1" class="collision" />
                                  <site name="site_R_thumb_pad" pos="0 0 -0.01" size="0.004 0.001 0.004" euler="0 0 1.57" type="box" rgba="0 1 0 0.5" group="4"/>
                                </body>
                              </body>
                            </body>
                          </body>
                          <body name="R_index_proximal" gravcomp="1" pos="0.026942 -0.0095 -0.11498" quat="0.999657 0 -0.026177 0">
                            <inertial pos="0 -0.0019982 -0.0131171" quat="0.707089 -0.00501356 0.00501356 0.707089" mass="0.0145412" diaginertia="1.95028e-06 1.95e-06 5.39716e-07" />
                            <joint name="R_index_MCP_joint" pos="0 0 0" axis="1 0 0" range="0 1.7" actuatorfrcrange="-1 1" damping="0.1" armature="0.005"/>
                            <geom mesh="R_index_proximal_0" material="black" class="visual" />
                            <geom mesh="R_index_proximal_1" material="sliver" class="visual" />
                            <geom mesh="R_index_proximal_0" class="collision" />
                            <geom mesh="R_index_proximal_1" class="collision" />
                            <body name="R_index_distal" gravcomp="1" pos="0 0.0011127 -0.031981">
                              <inertial pos="0 -0.00168936 -0.0153697" quat="0.996466 -0.0839918 0 0" mass="0.00905901" diaginertia="1.73e-06 1.72245e-06 2.07554e-07" />
                              <joint name="R_index_DIP_joint" pos="0 0 0" axis="1 0 0" range="0 1.6" actuatorfrcrange="-1 1" damping="0.1" armature="0.005"/>
                              <geom mesh="R_index_distal_0" material="black" class="visual" />
                              <geom mesh="R_index_distal_1" material="sliver" class="visual" />
                              <geom mesh="R_index_distal_0" class="collision" />
                              <geom mesh="R_index_distal_1" class="collision" />
                              <site name="site_R_index_pad" pos="0 0.005 -0.035" size="0.004 0.001 0.004" euler="0 0 0" type="box" rgba="0 1 0 0.5" group="4"/>
                            </body>
                          </body>
                          <body name="R_middle_proximal" gravcomp="1" pos="0.008 -0.0145 -0.128">
                            <inertial pos="0 -0.00115549 -0.0133419" quat="0.999362 -0.0357184 0 0" mass="0.0131311" diaginertia="1.94e-06 1.93716e-06 5.32843e-07" />
                            <joint name="R_middle_MCP_joint" pos="0 0 0" axis="1 0 0" range="0 1.7" actuatorfrcrange="-1 1" damping="0.1" armature="0.005"/>
                            <geom mesh="R_middle_proximal_0" material="black" class="visual" />
                            <geom mesh="R_middle_proximal_1" material="sliver" class="visual" />
                            <geom mesh="R_middle_proximal_0" class="collision" />
                            <geom mesh="R_middle_proximal_1" class="collision" />
                            <body name="R_middle_distal" gravcomp="1" pos="0 0.0029374 -0.031865">
                              <inertial pos="0 3.955e-05 -0.0154622" quat="0.990386 -0.138332 0 0" mass="0.00905901" diaginertia="1.73e-06 1.72396e-06 2.06037e-07" />
                              <joint name="R_middle_DIP_joint" pos="0 0 0" axis="1 0 0" range="0 1.6" actuatorfrcrange="-1 1" damping="0.1" armature="0.005"/>
                              <geom mesh="R_middle_distal_0" material="black" class="visual" />
                              <geom mesh="R_middle_distal_1" material="sliver" class="visual" />
                              <geom mesh="R_middle_distal_0" class="collision" />
                              <geom mesh="R_middle_distal_1" class="collision" />
                              <site name="site_R_middle_pad" pos="0 0.005 -0.037" size="0.004 0.001 0.004" euler="0 0 0" type="box" rgba="0 1 0 0.5" group="4"/>
                            </body>
                          </body>
                          <body name="R_ring_proximal" gravcomp="1" pos="-0.010942 -0.0095 -0.11998" quat="0.999657 0 0.026177 0">
                            <inertial pos="0 -0.0019982 -0.0131171" quat="0.707089 -0.00501356 0.00501356 0.707089" mass="0.0145412" diaginertia="1.95028e-06 1.95e-06 5.39716e-07" />
                            <joint name="R_ring_MCP_joint" pos="0 0 0" axis="1 0 0" range="0 1.7" actuatorfrcrange="-1 1" damping="0.1" armature="0.005"/>
                            <geom mesh="R_ring_proximal_0" material="sliver" class="visual" />
                            <geom mesh="R_ring_proximal_1" material="black" class="visual" />
                            <geom mesh="R_ring_proximal_0" class="collision" />
                            <geom mesh="R_ring_proximal_1" class="collision" />
                            <body name="R_ring_distal" gravcomp="1" pos="0 0.0011127 -0.031981">
                              <inertial pos="0 -0.00168936 -0.0153697" quat="0.996466 -0.0839918 0 0" mass="0.00905901" diaginertia="1.73e-06 1.72245e-06 2.07554e-07" />
                              <joint name="R_ring_DIP_joint" pos="0 0 0" axis="1 0 0" range="0 1.6" actuatorfrcrange="-1 1" damping="0.1" armature="0.005"/>
                              <geom mesh="R_ring_distal_0" material="black" class="visual" />
                              <geom mesh="R_ring_distal_1" material="sliver" class="visual" />
                              <geom mesh="R_ring_distal_0" class="collision" />
                              <geom mesh="R_ring_distal_1" class="collision" />
                              <site name="site_R_ring_pad" pos="0 0.006 -0.037" size="0.004 0.001 0.004" euler="0 0 0" type="box" rgba="0 1 0 0.5" group="4"/>
                            </body>
                          </body>
                          <body name="R_pinky_proximal" gravcomp="1" pos="-0.030194 -0.0045 -0.11287" quat="0.998135 0 0.061047 0">
                            <inertial pos="0 -0.00191046 -0.0132258" quat="0.707089 -0.00501356 0.00501356 0.707089" mass="0.0131311" diaginertia="1.94028e-06 1.94e-06 5.29716e-07" />
                            <joint name="R_pinky_MCP_joint" pos="0 0 0" axis="1 0 0" range="0 1.7" actuatorfrcrange="-1 1" damping="0.1" armature="0.005"/>
                            <geom mesh="R_pinky_proximal_0" material="black" class="visual" />
                            <geom mesh="R_pinky_proximal_1" material="sliver" class="visual" />
                            <geom mesh="R_pinky_proximal_0" class="collision" />
                            <geom mesh="R_pinky_proximal_1" class="collision" />
                            <body name="R_pinky_distal" gravcomp="1" pos="0 0.0011127 -0.031981">
                              <inertial pos="2.01e-06 -0.00260417 -0.0109989" quat="0.997444 -0.0714519 0 0" mass="0.00693901" diaginertia="8.6e-07 8.54401e-07 1.45599e-07" />
                              <joint name="R_pinky_DIP_joint" pos="0 0 0" axis="1 0 0" range="0 1.6" actuatorfrcrange="-1 1" damping="0.1" armature="0.005"/>
                              <geom mesh="R_pinky_distal_0" material="black" class="visual" />
                              <geom mesh="R_pinky_distal_1" material="sliver" class="visual" />
                              <geom mesh="R_pinky_distal_0" class="collision" />
                              <geom mesh="R_pinky_distal_1" class="collision" />
                              <site name="site_R_pinky_pad" pos="0 0.005 -0.026" size="0.004 0.001 0.004" euler="0 0 0" type="box" rgba="0 1 0 0.5" group="4"/>
                            </body>
                          </body>
                        </body>
                      </body>
                    </body>
                  </body>
                </body>
              </body>
            </body>
            <body name="neckYaw" pos="-0.013 0 0.29855">
              <inertial pos="0.0229166 -0.00099716 0.100187" quat="0.528239 -0.102157 -0.0585684 0.840891" mass="0.412424" diaginertia="0.00129645 0.00128003 0.00012854" />
              <joint name="neckYaw" pos="0 0 0" axis="0 0 1" range="-1.571 1.571" actuatorfrcrange="-6.4 6.4" damping="1" armature="0.01"/>
              <geom material="black" mesh="neckYaw" class="visual" />
              <geom mesh="neckYaw" class="collision" />
              <body name="neckPitch" pos="0.0316 0.02 0.14595">
                <inertial pos="0.0179036 -0.0204662 0.0459628" quat="-0.0121246 0.522948 -0.00798363 0.852241" mass="0.997409" diaginertia="0.00377643 0.00354675 0.00235768" />
                <joint name="neckPitch" pos="0 0 0" axis="0 1 0" range="-0.873 0.873" actuatorfrcrange="-6.4 6.4" damping="1" armature="0.01"/>
                <geom material="black" mesh="neckPitch" class="visual" />
                <geom mesh="neckPitch" class="collision" />
              </body>
            </body>
          </body>
        </body>
      </body>
    </body>
  </worldbody>

<actuator>
    <position name="waistRoll"  joint="waistRoll"  kp="2000"  kv="800" forcerange="-110 110" ctrllimited="true" ctrlrange="-0.279 0.279"/>
    <position name="waistPitch" joint="waistPitch" kp="2000"  kv="600" forcerange="-110 110" ctrllimited="true" ctrlrange="-0.663 1.361"/>
    <position name="waistYaw"   joint="waistYaw"   kp="2000"  kv="600" forcerange="-110 110" ctrllimited="true" ctrlrange="-0.829 0.829"/>

    <position name="neckYaw"   joint="neckYaw"   kp="200" kv="20" forcerange="-6.4 6.4" ctrllimited="true" ctrlrange="-1.571 1.571"/>
    <position name="neckPitch" joint="neckPitch" kp="200" kv="20" forcerange="-6.4 6.4" ctrllimited="true" ctrlrange="-0.873 0.873"/>

    <position name="shoulderPitch_Left"  joint="shoulderPitch_Left"  kp="800" kv="80" forcerange="-65 65" ctrllimited="true" ctrlrange="-3.613 2.042"/>
    <position name="shoulderRoll_Left"   joint="shoulderRoll_Left"   kp="800" kv="80" forcerange="-65 65" ctrllimited="true" ctrlrange="-0.628 2.793"/>
    <position name="shoulderYaw_Left"    joint="shoulderYaw_Left"    kp="800" kv="80" forcerange="-65 65" ctrllimited="true" ctrlrange="-2.583 2.583"/>
    <position name="elbow_Left"          joint="elbow_Left"          kp="800" kv="80" forcerange="-30 30" ctrllimited="true" ctrlrange="-2.496 0.209"/>

    <position name="wristYaw_Left"   joint="wristYaw_Left"   kp="500" kv="50" forcerange="-6.4 6.4" ctrllimited="true" ctrlrange="-2.67 2.67"/>
    <position name="wristPitch_Left" joint="wristPitch_Left" kp="500" kv="50" forcerange="-6.4 6.4" ctrllimited="true" ctrlrange="-0.96 0.96"/>
    <position name="wristRoll_Left"  joint="wristRoll_Left"  kp="500" kv="50" forcerange="-6.4 6.4" ctrllimited="true" ctrlrange="-0.96 0.96"/>

    <position name="L_thumb_MCP_joint1" joint="L_thumb_MCP_joint1" kp="150" kv="15" forcerange="-10 10" ctrllimited="true" ctrlrange="0 1.1"/>
    <position name="L_thumb_MCP_joint2" joint="L_thumb_MCP_joint2" kp="150" kv="15" forcerange="-10 10" ctrllimited="true" ctrlrange="0 0.5"/>
    <position name="L_thumb_PIP_joint"  joint="L_thumb_PIP_joint"  kp="150" kv="15" forcerange="-10 10" ctrllimited="true" ctrlrange="0 1"/>
    <position name="L_thumb_DIP_joint"  joint="L_thumb_DIP_joint"  kp="150" kv="15" forcerange="-10 10" ctrllimited="true" ctrlrange="0 1.2"/>
    
    <position name="L_index_MCP_joint"  joint="L_index_MCP_joint"  kp="150" kv="15" forcerange="-10 10" ctrllimited="true" ctrlrange="0 1.7"/>
    <position name="L_index_DIP_joint"  joint="L_index_DIP_joint"  kp="150" kv="15" forcerange="-10 10" ctrllimited="true" ctrlrange="0 1.6"/>
    
    <position name="L_middle_MCP_joint" joint="L_middle_MCP_joint" kp="150" kv="15" forcerange="-10 10" ctrllimited="true" ctrlrange="0 1.7"/>
    <position name="L_middle_DIP_joint" joint="L_middle_DIP_joint" kp="150" kv="15" forcerange="-10 10" ctrllimited="true" ctrlrange="0 1.6"/>
    
    <position name="L_ring_MCP_joint"   joint="L_ring_MCP_joint"   kp="150" kv="15" forcerange="-10 10" ctrllimited="true" ctrlrange="0 1.7"/>
    <position name="L_ring_DIP_joint"   joint="L_ring_DIP_joint"   kp="150" kv="15" forcerange="-10 10" ctrllimited="true" ctrlrange="0 1.6"/>
    
    <position name="L_pinky_MCP_joint"  joint="L_pinky_MCP_joint"  kp="150" kv="15" forcerange="-10 10" ctrllimited="true" ctrlrange="0 1.7"/>
    <position name="L_pinky_DIP_joint"  joint="L_pinky_DIP_joint"  kp="150" kv="15" forcerange="-10 10" ctrllimited="true" ctrlrange="0 1.6"/>

    <position name="shoulderPitch_Right" joint="shoulderPitch_Right" kp="800" kv="80" forcerange="-65 65" ctrllimited="true" ctrlrange="-3.613 2.042"/>
    <position name="shoulderRoll_Right"  joint="shoulderRoll_Right"  kp="800" kv="80" forcerange="-65 65" ctrllimited="true" ctrlrange="-2.793 0.628"/>
    <position name="shoulderYaw_Right"   joint="shoulderYaw_Right"   kp="800" kv="80" forcerange="-65 65" ctrllimited="true" ctrlrange="-2.583 2.583"/>
    <position name="elbow_Right"         joint="elbow_Right"         kp="800" kv="80" forcerange="-30 30" ctrllimited="true" ctrlrange="-2.496 0.209"/>

    <position name="wristYaw_Right"   joint="wristYaw_Right"   kp="500" kv="50" forcerange="-6.4 6.4" ctrllimited="true" ctrlrange="-2.67 2.67"/>
    <position name="wristPitch_Right" joint="wristPitch_Right" kp="500" kv="50" forcerange="-6.4 6.4" ctrllimited="true" ctrlrange="-0.96 0.96"/>
    <position name="wristRoll_Right"  joint="wristRoll_Right"  kp="500" kv="50" forcerange="-6.4 6.4" ctrllimited="true" ctrlrange="-0.96 0.96"/>

    <position name="R_thumb_MCP_joint1" joint="R_thumb_MCP_joint1" kp="150" kv="15" forcerange="-10 10" ctrllimited="true" ctrlrange="0 1.1"/>
    <position name="R_thumb_MCP_joint2" joint="R_thumb_MCP_joint2" kp="150" kv="15" forcerange="-10 10" ctrllimited="true" ctrlrange="0 0.5"/>
    <position name="R_thumb_PIP_joint"  joint="R_thumb_PIP_joint"  kp="150" kv="15" forcerange="-10 10" ctrllimited="true" ctrlrange="0 1"/>
    <position name="R_thumb_DIP_joint"  joint="R_thumb_DIP_joint"  kp="150" kv="15" forcerange="-10 10" ctrllimited="true" ctrlrange="0 1.2"/>
    
    <position name="R_index_MCP_joint"  joint="R_index_MCP_joint"  kp="150" kv="15" forcerange="-10 10" ctrllimited="true" ctrlrange="0 1.7"/>
    <position name="R_index_DIP_joint"  joint="R_index_DIP_joint"  kp="150" kv="15" forcerange="-10 10" ctrllimited="true" ctrlrange="0 1.6"/>
    
    <position name="R_middle_MCP_joint" joint="R_middle_MCP_joint" kp="150" kv="15" forcerange="-10 10" ctrllimited="true" ctrlrange="0 1.7"/>
    <position name="R_middle_DIP_joint" joint="R_middle_DIP_joint" kp="150" kv="15" forcerange="-10 10" ctrllimited="true" ctrlrange="0 1.6"/>
    
    <position name="R_ring_MCP_joint"   joint="R_ring_MCP_joint"   kp="150" kv="15" forcerange="-10 10" ctrllimited="true" ctrlrange="0 1.7"/>
    <position name="R_ring_DIP_joint"   joint="R_ring_DIP_joint"   kp="150" kv="15" forcerange="-10 10" ctrllimited="true" ctrlrange="0 1.6"/>
    
    <position name="R_pinky_MCP_joint"  joint="R_pinky_MCP_joint"  kp="150" kv="15" forcerange="-10 10" ctrllimited="true" ctrlrange="0 1.7"/>
    <position name="R_pinky_DIP_joint"  joint="R_pinky_DIP_joint"  kp="150" kv="15" forcerange="-10 10" ctrllimited="true" ctrlrange="0 1.6"/>
  </actuator>

  <sensor>
    <jointpos name="pos_waistRoll" joint="waistRoll" />
    <jointpos name="pos_waistPitch" joint="waistPitch" />
    <jointpos name="pos_waistYaw" joint="waistYaw" />
    <jointpos name="pos_shoulderPitch_Left" joint="shoulderPitch_Left" />
    <jointpos name="pos_shoulderRoll_Left" joint="shoulderRoll_Left" />
    <jointpos name="pos_shoulderYaw_Left" joint="shoulderYaw_Left" />
    <jointpos name="pos_elbow_Left" joint="elbow_Left" />
    <jointpos name="pos_wristYaw_Left" joint="wristYaw_Left" />
    <jointpos name="pos_wristPitch_Left" joint="wristPitch_Left" />
    <jointpos name="pos_wristRoll_Left" joint="wristRoll_Left" />
    <jointpos name="pos_L_thumb_MCP_joint1" joint="L_thumb_MCP_joint1" />
    <jointpos name="pos_L_thumb_MCP_joint2" joint="L_thumb_MCP_joint2" />
    <jointpos name="pos_L_thumb_PIP_joint" joint="L_thumb_PIP_joint" />
    <jointpos name="pos_L_thumb_DIP_joint" joint="L_thumb_DIP_joint" />
    <jointpos name="pos_L_index_MCP_joint" joint="L_index_MCP_joint" />
    <jointpos name="pos_L_index_DIP_joint" joint="L_index_DIP_joint" />
    <jointpos name="pos_L_middle_MCP_joint" joint="L_middle_MCP_joint" />
    <jointpos name="pos_L_middle_DIP_joint" joint="L_middle_DIP_joint" />
    <jointpos name="pos_L_ring_MCP_joint" joint="L_ring_MCP_joint" />
    <jointpos name="pos_L_ring_DIP_joint" joint="L_ring_DIP_joint" />
    <jointpos name="pos_L_pinky_MCP_joint" joint="L_pinky_MCP_joint" />
    <jointpos name="pos_L_pinky_DIP_joint" joint="L_pinky_DIP_joint" />
    <jointpos name="pos_shoulderPitch_Right" joint="shoulderPitch_Right" />
    <jointpos name="pos_shoulderRoll_Right" joint="shoulderRoll_Right" />
    <jointpos name="pos_shoulderYaw_Right" joint="shoulderYaw_Right" />
    <jointpos name="pos_elbow_Right" joint="elbow_Right" />
    <jointpos name="pos_wristYaw_Right" joint="wristYaw_Right" />
    <jointpos name="pos_wristPitch_Right" joint="wristPitch_Right" />
    <jointpos name="pos_wristRoll_Right" joint="wristRoll_Right" />
    <jointpos name="pos_R_thumb_MCP_joint1" joint="R_thumb_MCP_joint1" />
    <jointpos name="pos_R_thumb_MCP_joint2" joint="R_thumb_MCP_joint2" />
    <jointpos name="pos_R_thumb_PIP_joint" joint="R_thumb_PIP_joint" />
    <jointpos name="pos_R_thumb_DIP_joint" joint="R_thumb_DIP_joint" />
    <jointpos name="pos_R_index_MCP_joint" joint="R_index_MCP_joint" />
    <jointpos name="pos_R_index_DIP_joint" joint="R_index_DIP_joint" />
    <jointpos name="pos_R_middle_MCP_joint" joint="R_middle_MCP_joint" />
    <jointpos name="pos_R_middle_DIP_joint" joint="R_middle_DIP_joint" />
    <jointpos name="pos_R_ring_MCP_joint" joint="R_ring_MCP_joint" />
    <jointpos name="pos_R_ring_DIP_joint" joint="R_ring_DIP_joint" />
    <jointpos name="pos_R_pinky_MCP_joint" joint="R_pinky_MCP_joint" />
    <jointpos name="pos_R_pinky_DIP_joint" joint="R_pinky_DIP_joint" />
    <jointpos name="pos_neckYaw" joint="neckYaw" />
    <jointpos name="pos_neckPitch" joint="neckPitch" />
    <jointvel name="vel_waistRoll" joint="waistRoll" />
    <jointvel name="vel_waistPitch" joint="waistPitch" />
    <jointvel name="vel_waistYaw" joint="waistYaw" />
    <jointvel name="vel_shoulderPitch_Left" joint="shoulderPitch_Left" />
    <jointvel name="vel_shoulderRoll_Left" joint="shoulderRoll_Left" />
    <jointvel name="vel_shoulderYaw_Left" joint="shoulderYaw_Left" />
    <jointvel name="vel_elbow_Left" joint="elbow_Left" />
    <jointvel name="vel_wristYaw_Left" joint="wristYaw_Left" />
    <jointvel name="vel_wristPitch_Left" joint="wristPitch_Left" />
    <jointvel name="vel_wristRoll_Left" joint="wristRoll_Left" />
    <jointvel name="vel_L_thumb_MCP_joint1" joint="L_thumb_MCP_joint1" />
    <jointvel name="vel_L_thumb_MCP_joint2" joint="L_thumb_MCP_joint2" />
    <jointvel name="vel_L_thumb_PIP_joint" joint="L_thumb_PIP_joint" />
    <jointvel name="vel_L_thumb_DIP_joint" joint="L_thumb_DIP_joint" />
    <jointvel name="vel_L_index_MCP_joint" joint="L_index_MCP_joint" />
    <jointvel name="vel_L_index_DIP_joint" joint="L_index_DIP_joint" />
    <jointvel name="vel_L_middle_MCP_joint" joint="L_middle_MCP_joint" />
    <jointvel name="vel_L_middle_DIP_joint" joint="L_middle_DIP_joint" />
    <jointvel name="vel_L_ring_MCP_joint" joint="L_ring_MCP_joint" />
    <jointvel name="vel_L_ring_DIP_joint" joint="L_ring_DIP_joint" />
    <jointvel name="vel_L_pinky_MCP_joint" joint="L_pinky_MCP_joint" />
    <jointvel name="vel_L_pinky_DIP_joint" joint="L_pinky_DIP_joint" />
    <jointvel name="vel_shoulderPitch_Right" joint="shoulderPitch_Right" />
    <jointvel name="vel_shoulderRoll_Right" joint="shoulderRoll_Right" />
    <jointvel name="vel_shoulderYaw_Right" joint="shoulderYaw_Right" />
    <jointvel name="vel_elbow_Right" joint="elbow_Right" />
    <jointvel name="vel_wristYaw_Right" joint="wristYaw_Right" />
    <jointvel name="vel_wristPitch_Right" joint="wristPitch_Right" />
    <jointvel name="vel_wristRoll_Right" joint="wristRoll_Right" />
    <jointvel name="vel_R_thumb_MCP_joint1" joint="R_thumb_MCP_joint1" />
    <jointvel name="vel_R_thumb_MCP_joint2" joint="R_thumb_MCP_joint2" />
    <jointvel name="vel_R_thumb_PIP_joint" joint="R_thumb_PIP_joint" />
    <jointvel name="vel_R_thumb_DIP_joint" joint="R_thumb_DIP_joint" />
    <jointvel name="vel_R_index_MCP_joint" joint="R_index_MCP_joint" />
    <jointvel name="vel_R_index_DIP_joint" joint="R_index_DIP_joint" />
    <jointvel name="vel_R_middle_MCP_joint" joint="R_middle_MCP_joint" />
    <jointvel name="vel_R_middle_DIP_joint" joint="R_middle_DIP_joint" />
    <jointvel name="vel_R_ring_MCP_joint" joint="R_ring_MCP_joint" />
    <jointvel name="vel_R_ring_DIP_joint" joint="R_ring_DIP_joint" />
    <jointvel name="vel_R_pinky_MCP_joint" joint="R_pinky_MCP_joint" />
    <jointvel name="vel_R_pinky_DIP_joint" joint="R_pinky_DIP_joint" />
    <jointvel name="vel_neckYaw" joint="neckYaw" />
    <jointvel name="vel_neckPitch" joint="neckPitch" />
    <jointactuatorfrc name="force_waistRoll" joint="waistRoll" />
    <jointactuatorfrc name="force_waistPitch" joint="waistPitch" />
    <jointactuatorfrc name="force_waistYaw" joint="waistYaw" />
    <jointactuatorfrc name="force_shoulderPitch_Left" joint="shoulderPitch_Left" />
    <jointactuatorfrc name="force_shoulderRoll_Left" joint="shoulderRoll_Left" />
    <jointactuatorfrc name="force_shoulderYaw_Left" joint="shoulderYaw_Left" />
    <jointactuatorfrc name="force_elbow_Left" joint="elbow_Left" />
    <jointactuatorfrc name="force_wristYaw_Left" joint="wristYaw_Left" />
    <jointactuatorfrc name="force_wristPitch_Left" joint="wristPitch_Left" />
    <jointactuatorfrc name="force_wristRoll_Left" joint="wristRoll_Left" />
    <jointactuatorfrc name="force_L_thumb_MCP_joint1" joint="L_thumb_MCP_joint1" />
    <jointactuatorfrc name="force_L_thumb_MCP_joint2" joint="L_thumb_MCP_joint2" />
    <jointactuatorfrc name="force_L_thumb_PIP_joint" joint="L_thumb_PIP_joint" />
    <jointactuatorfrc name="force_L_thumb_DIP_joint" joint="L_thumb_DIP_joint" />
    <jointactuatorfrc name="force_L_index_MCP_joint" joint="L_index_MCP_joint" />
    <jointactuatorfrc name="force_L_index_DIP_joint" joint="L_index_DIP_joint" />
    <jointactuatorfrc name="force_L_middle_MCP_joint" joint="L_middle_MCP_joint" />
    <jointactuatorfrc name="force_L_middle_DIP_joint" joint="L_middle_DIP_joint" />
    <jointactuatorfrc name="force_L_ring_MCP_joint" joint="L_ring_MCP_joint" />
    <jointactuatorfrc name="force_L_ring_DIP_joint" joint="L_ring_DIP_joint" />
    <jointactuatorfrc name="force_L_pinky_MCP_joint" joint="L_pinky_MCP_joint" />
    <jointactuatorfrc name="force_L_pinky_DIP_joint" joint="L_pinky_DIP_joint" />
    <jointactuatorfrc name="force_shoulderPitch_Right" joint="shoulderPitch_Right" />
    <jointactuatorfrc name="force_shoulderRoll_Right" joint="shoulderRoll_Right" />
    <jointactuatorfrc name="force_shoulderYaw_Right" joint="shoulderYaw_Right" />
    <jointactuatorfrc name="force_elbow_Right" joint="elbow_Right" />
    <jointactuatorfrc name="force_wristYaw_Right" joint="wristYaw_Right" />
    <jointactuatorfrc name="force_wristPitch_Right" joint="wristPitch_Right" />
    <jointactuatorfrc name="force_wristRoll_Right" joint="wristRoll_Right" />
    <jointactuatorfrc name="force_R_thumb_MCP_joint1" joint="R_thumb_MCP_joint1" />
    <jointactuatorfrc name="force_R_thumb_MCP_joint2" joint="R_thumb_MCP_joint2" />
    <jointactuatorfrc name="force_R_thumb_PIP_joint" joint="R_thumb_PIP_joint" />
    <jointactuatorfrc name="force_R_thumb_DIP_joint" joint="R_thumb_DIP_joint" />
    <jointactuatorfrc name="force_R_index_MCP_joint" joint="R_index_MCP_joint" />
    <jointactuatorfrc name="force_R_index_DIP_joint" joint="R_index_DIP_joint" />
    <jointactuatorfrc name="force_R_middle_MCP_joint" joint="R_middle_MCP_joint" />
    <jointactuatorfrc name="force_R_middle_DIP_joint" joint="R_middle_DIP_joint" />
    <jointactuatorfrc name="force_R_ring_MCP_joint" joint="R_ring_MCP_joint" />
    <jointactuatorfrc name="force_R_ring_DIP_joint" joint="R_ring_DIP_joint" />
    <jointactuatorfrc name="force_R_pinky_MCP_joint" joint="R_pinky_MCP_joint" />
    <jointactuatorfrc name="force_R_pinky_DIP_joint" joint="R_pinky_DIP_joint" />
    <jointactuatorfrc name="force_neckYaw" joint="neckYaw" />
    <jointactuatorfrc name="force_neckPitch" joint="neckPitch" />

    <force  name="left_fts_sensor_force"  site="left_palm_fts"/>
    <torque name="left_fts_sensor_torque" site="left_palm_fts"/>
    
    <force  name="right_fts_sensor_force" site="right_palm_fts"/>
    <torque name="right_fts_sensor_torque" site="right_palm_fts"/>

    <force  name="L_thumb_pad_force"  site="site_L_thumb_pad"/>
    <torque name="L_thumb_pad_torque" site="site_L_thumb_pad"/>
    
    <force  name="L_index_pad_force"  site="site_L_index_pad"/>
    <torque name="L_index_pad_torque" site="site_L_index_pad"/>
    
    <force  name="L_middle_pad_force"  site="site_L_middle_pad"/>
    <torque name="L_middle_pad_torque" site="site_L_middle_pad"/>
    
    <force  name="L_ring_pad_force"  site="site_L_ring_pad"/>
    <torque name="L_ring_pad_torque" site="site_L_ring_pad"/>
    
    <force  name="L_pinky_pad_force"  site="site_L_pinky_pad"/>
    <torque name="L_pinky_pad_torque" site="site_L_pinky_pad"/>

    <force  name="R_thumb_pad_force"  site="site_R_thumb_pad"/>
    <torque name="R_thumb_pad_torque" site="site_R_thumb_pad"/>
    
    <force  name="R_index_pad_force"  site="site_R_index_pad"/>
    <torque name="R_index_pad_torque" site="site_R_index_pad"/>
    
    <force  name="R_middle_pad_force"  site="site_R_middle_pad"/>
    <torque name="R_middle_pad_torque" site="site_R_middle_pad"/>
    
    <force  name="R_ring_pad_force"  site="site_R_ring_pad"/>
    <torque name="R_ring_pad_torque" site="site_R_ring_pad"/>
    
    <force  name="R_pinky_pad_force"  site="site_R_pinky_pad"/>
    <torque name="R_pinky_pad_torque" site="site_R_pinky_pad"/>

  </sensor>
</mujoco>