<mujoco model="conveyor_belt">

  <worldbody>
    <body name="conveyor" pos="0.45  -2.0 1.05">
      <joint name="conveyor_linear" type="slide" axis="0 1 0" solreflimit=".08 1" damping="5e-4"/>
      <geom name="belt" type="box" size="0.3 100.0 0.04"  mass="1000" rgba="0.3 0.3 0.3 1" friction="1.0 1.0 1.0"
      solimp="0.95 0.9999 0.001 0.5 2.0" solref="0.004 1.0" priority="1"/>
    </body>

    
    <body name="target_box_1" pos="0.55 -2.5 1.15" quat="1 0 0 0">
      <geom name="target_box_1_geom" type="box" size="0.05 0.05 0.05" rgba="1 0 0 1" mass="0.5"
            friction="0.8 0.01 0.01"/>
      <joint name="target_box_1_joint" type="free"/>
    </body>

    <body name="target_box_2" pos="0.55 -3.0 1.15" quat="1 0 0 0">
      <geom name="target_box_2_geom" type="box" size="0.05 0.05 0.05" rgba="0 1 0 1" mass="0.5"
            friction="0.8 0.01 0.01"/>
      <joint name="target_box_2_joint" type="free"/>
    </body>

    <body name="target_box_3" pos="0.55 -3.5 1.15" quat="1 0 0 0">
      <geom name="target_box_3_geom" type="box" size="0.05 0.05 0.05" rgba="0 0 1 1" mass="0.5"
            friction="0.8 0.01 0.01"/>
      <joint name="target_box_3_joint" type="free"/>
    </body>


  </worldbody>
    <actuator>
        <velocity name="slide" joint="conveyor_linear" kv="10000" ctrllimited="true" ctrlrange="-1 1"/>
    </actuator>
</mujoco>