<?xml version='1.0' encoding='utf-8'?>
<robot name="adam_u">
<link name="world" />
 <link name="conveyor_base">
  </link> 
<joint name="world_to_conveyor" type="fixed">
    <parent link="world"/>
    <child link="conveyor_base"/>
    <origin xyz="0.6 0 1.05" rpy="0 0 0"/> </joint>

<link name="conveyor_belt_link">
     </link>

<joint name="conveyor_linear" type="prismatic">
    <parent link="conveyor_base"/>
    <child link="conveyor_belt_link"/>
    <axis xyz="0 1 0"/> <limit lower="-100" upper="100" effort="1000" velocity="2.0"/>
</joint> 
<joint name="world_to_robot" type="fixed">
  <parent link="world"/>
  <child link="lifting_Columns"/>
  <origin xyz="0 0 1.05" rpy="0 0 0"/> 
</joint>
  <link name="lifting_Columns">
    <inertial>
      <origin xyz="9.0363503544396E-05 -3.16722893624041E-05 -0.722724623743624" rpy="0 0 0" />
      <mass value="16.1204633267776" />
      <inertia ixx="0.582930853390889" ixy="8.29673282362914E-06" ixz="-0.000193074913370059" iyy="0.351926408749018" iyz="4.4035399598838E-06" izz="0.720002300370631" />
    </inertial>
    <visual>
      <origin xyz="0 0 0" rpy="0 0 0" />
      <geometry>
        <mesh filename="package://adamu_description/meshes/visual/lifting_Columns.dae" />
      </geometry>
      <material name="">
        <color rgba="1 1 1 1" />
      </material>
    </visual>
    <collision>
      <origin xyz="0 0 0" rpy="0 0 0" />
      <geometry>
        <mesh filename="package://adamu_description/meshes/collision/lifting_Columns.STL" />
      </geometry>
    </collision>
  </link>
  <link name="waistRoll">
    <inertial>
      <origin xyz="0.00093826 0.00093832 0.03999995" rpy="0 0 0" />
      <mass value="2.36268465" />
      <inertia ixx="0.00543041" ixy="-0.00000171" ixz="-0.00006791" iyy="0.00543044" iyz="0.00006793" izz="0.00184993" />
    </inertial>
    <visual>
      <origin xyz="0 0 0" rpy="0 0 0" />
      <geometry>
        <mesh filename="package://adamu_description/meshes/visual/waistRoll.dae" />
      </geometry>
      <material name="">
        <color rgba="1 1 1 1" />
      </material>
    </visual>
    <collision>
      <origin xyz="0 0 0" rpy="0 0 0" />
      <geometry>
        <mesh filename="package://adamu_description/meshes/collision/waistRoll.STL" />
      </geometry>
    </collision>
  </link>
  <joint name="waistRoll" type="revolute">
    <origin xyz="0 0 0.0767" rpy="0 0 0" />
    <parent link="lifting_Columns" />
    <child link="waistRoll" />
    <axis xyz="1 0 0" />
    <limit lower="-0.279" upper="0.279" effort="110" velocity="8" />
  </joint>
  <link name="waistPitch">
    <inertial>
      <origin xyz="-0.00008401 0.00189362 0.02548321" rpy="0 0 0" />
      <mass value="0.56353776" />
      <inertia ixx="0.00151470" ixy="0.00001037" ixz="0.00000444" iyy="0.00067279" iyz="-0.00001192" izz="0.00155907" />
    </inertial>
    <visual>
      <origin xyz="0 0 0" rpy="0 0 0" />
      <geometry>
        <mesh filename="package://adamu_description/meshes/visual/waistPitch.dae" />
      </geometry>
      <material name="">
        <color rgba="1 1 1 1" />
      </material>
    </visual>
    <collision>
      <origin xyz="0 0 0" rpy="0 0 0" />
      <geometry>
        <mesh filename="package://adamu_description/meshes/collision/waistPitch.STL" />
      </geometry>
    </collision>
  </link>
  <joint name="waistPitch" type="revolute">
    <origin xyz="0 0 0.08" rpy="0 0 0" />
    <parent link="waistRoll" />
    <child link="waistPitch" />
    <axis xyz="0 1 0" />
    <limit lower="-0.663" upper="1.361" effort="110" velocity="8" />
  </joint>
  <link name="torso">
    <inertial>
      <origin xyz="-0.00189583 0.00055253 0.16331711" rpy="0 0 0" />
      <mass value="12.22987423" />
      <inertia ixx="0.11728047" ixy="-0.00035191" ixz="-0.00379829" iyy="0.08214981" iyz="-0.00000303" izz="0.06451327" />
    </inertial>
    <visual>
      <origin xyz="0 0 0" rpy="0 0 0" />
      <geometry>
        <mesh filename="package://adamu_description/meshes/visual/torso.dae" />
      </geometry>
      <material name="">
        <color rgba="1 1 1 1" />
      </material>
    </visual>
    <collision>
      <origin xyz="0 0 0" rpy="0 0 0" />
      <geometry>
        <mesh filename="package://adamu_description/meshes/collision/torso.STL" />
      </geometry>
    </collision>
  </link>
  <joint name="waistYaw" type="revolute">
    <origin xyz="0 0.0005 0.053" rpy="0 0 0" />
    <parent link="waistPitch" />
    <child link="torso" />
    <axis xyz="0 0 1" />
    <limit lower="-0.829" upper="0.829" effort="110" velocity="8" />
  </joint>
  <link name="shoulderPitchLeft">
    <inertial>
      <origin xyz="-0.00066946 0.02639720 0.00000000" rpy="0 0 0" />
      <mass value="0.21653557" />
      <inertia ixx="0.00018644" ixy="-0.00000226" ixz="0.00000000" iyy="0.00030720" iyz="0.00000000" izz="0.00036960" />
    </inertial>
    <visual>
      <origin xyz="0 0 0" rpy="0 0 0" />
      <geometry>
        <mesh filename="package://adamu_description/meshes/visual/shoulderPitchLeft.dae" />
      </geometry>
      <material name="">
        <color rgba="1 1 1 1" />
      </material>
    </visual>
    <collision>
      <origin xyz="0 0 0" rpy="0 0 0" />
      <geometry>
        <mesh filename="package://adamu_description/meshes/collision/shoulderPitchLeft.STL" />
      </geometry>
    </collision>
  </link>
  <joint name="shoulderPitch_Left" type="revolute">
    <origin xyz="0 0.16049 0.25755" rpy="0.34907 0 0" />
    <parent link="torso" />
    <child link="shoulderPitchLeft" />
    <axis xyz="0 1 0" />
    <limit lower="-3.613" upper="2.042" effort="65" velocity="8" />
  </joint>
  <link name="shoulderRollLeft">
    <inertial>
      <origin xyz="-0.03330224 0.00736791 -0.00952035" rpy="0 0 0" />
      <mass value="0.74622709" />
      <inertia ixx="0.00080156" ixy="0.00001081" ixz="-0.00000860" iyy="0.00063275" iyz="-0.00020980" izz="0.00054165" />
    </inertial>
    <visual>
      <origin xyz="0 0 0" rpy="0 0 0" />
      <geometry>
        <mesh filename="package://adamu_description/meshes/visual/shoulderRollLeft.dae" />
      </geometry>
      <material name="">
        <color rgba="1 1 1 1" />
      </material>
    </visual>
    <collision>
      <origin xyz="0 0 0" rpy="0 0 0" />
      <geometry>
        <mesh filename="package://adamu_description/meshes/collision/shoulderRollLeft.STL" />
      </geometry>
    </collision>
  </link>
  <joint name="shoulderRoll_Left" type="revolute">
    <origin xyz="0.0335 0.0435 0" rpy="-0.34907 0 0" />
    <parent link="shoulderPitchLeft" />
    <child link="shoulderRollLeft" />
    <axis xyz="1 0 0" />
    <limit lower="-0.628" upper="2.793" effort="65" velocity="8" />
  </joint>
  <link name="shoulderYawLeft">
    <inertial>
      <origin xyz="-0.00062397 -0.00062667 -0.08122190" rpy="0 0 0" />
      <mass value="0.76573936" />
      <inertia ixx="0.00351292" ixy="-0.00000012" ixz="0.00004947" iyy="0.00340267" iyz="0.00006115" izz="0.00046387" />
    </inertial>
    <visual>
      <origin xyz="0 0 0" rpy="0 0 0" />
      <geometry>
        <mesh filename="package://adamu_description/meshes/visual/shoulderYawLeft.dae" />
      </geometry>
      <material name="">
        <color rgba="1 1 1 1" />
      </material>
    </visual>
    <collision>
      <origin xyz="0 0 0" rpy="0 0 0" />
      <geometry>
        <mesh filename="package://adamu_description/meshes/collision/shoulderYawLeft.STL" />
      </geometry>
    </collision>
  </link>
  <joint name="shoulderYaw_Left" type="revolute">
    <origin xyz="-0.0335 0.034 -0.0585" rpy="0 0 0" />
    <parent link="shoulderRollLeft" />
    <child link="shoulderYawLeft" />
    <axis xyz="0 0 1" />
    <limit lower="-2.583" upper="2.583" effort="65" velocity="8" />
  </joint>
  <link name="elbowLeft">
    <inertial>
      <origin xyz="-0.01366863 0.02914387 -0.02351344" rpy="0 0 0" />
      <mass value="0.87761532" />
      <inertia ixx="0.00085104" ixy="0.00000786" ixz="0.00024135" iyy="0.00099271" iyz="0.00001473" izz="0.00055926" />
    </inertial>
    <visual>
      <origin xyz="0 0 0" rpy="0 0 0" />
      <geometry>
        <mesh filename="package://adamu_description/meshes/visual/elbowLeft.dae" />
      </geometry>
      <material name="">
        <color rgba="0.752941176470588 0.752941176470588 0.752941176470588 1" />
      </material>
    </visual>
    <collision>
      <origin xyz="0 0 0" rpy="0 0 0" />
      <geometry>
        <mesh filename="package://adamu_description/meshes/collision/elbowLeft.STL" />
      </geometry>
    </collision>
  </link>
  <joint name="elbow_Left" type="revolute">
    <origin xyz="0 -0.0285 -0.20415" rpy="0 0 0" />
    <parent link="shoulderYawLeft" />
    <child link="elbowLeft" />
    <axis xyz="0 1 0" />
    <limit lower="-2.496" upper="0.209" effort="30" velocity="8" />
  </joint>
  <link name="wristYawLeft">
    <inertial>
      <origin xyz="-0.00204137 0.00010627 -0.09216777" rpy="0 0 0" />
      <mass value="0.95587869" />
      <inertia ixx="0.00256138" ixy="-0.00000268" ixz="0.00003060" iyy="0.00250125" iyz="-0.00002660" izz="0.00055105" />
    </inertial>
    <visual>
      <origin xyz="0 0 0" rpy="0 0 0" />
      <geometry>
        <mesh filename="package://adamu_description/meshes/visual/wristYawLeft.dae" />
      </geometry>
      <material name="">
        <color rgba="0.752941176470588 0.752941176470588 0.752941176470588 1" />
      </material>
    </visual>
    <collision>
      <origin xyz="0 0 0" rpy="0 0 0" />
      <geometry>
        <mesh filename="package://adamu_description/meshes/collision/wristYawLeft.STL" />
      </geometry>
    </collision>
  </link>
  <joint name="wristYaw_Left" type="revolute">
    <origin xyz="-0.025 0.0285 -0.0729" rpy="0 0 0" />
    <parent link="elbowLeft" />
    <child link="wristYawLeft" />
    <axis xyz="0 0 1" />
    <limit lower="-2.67" upper="2.67" effort="6.4" velocity="5" />
  </joint>
  <link name="wristPitchLeft">
    <inertial>
      <origin xyz="-0.00017582 0.00166098 -0.00002773" rpy="0 0 0" />
      <mass value="0.11963454" />
      <inertia ixx="0.00003359" ixy="0.00000002" ixz="0.00000000" iyy="0.00002690" iyz="-0.00000005" izz="0.00003977" />
    </inertial>
    <visual>
      <origin xyz="0 0 0" rpy="0 0 0" />
      <geometry>
        <mesh filename="package://adamu_description/meshes/visual/wristPitchLeft.dae" />
      </geometry>
      <material name="">
        <color rgba="0.752941176470588 0.752941176470588 0.752941176470588 1" />
      </material>
    </visual>
    <collision>
      <origin xyz="0 0 0" rpy="0 0 0" />
      <geometry>
        <mesh filename="package://adamu_description/meshes/collision/wristPitchLeft.STL" />
      </geometry>
    </collision>
  </link>
  <joint name="wristPitch_Left" type="revolute">
    <origin xyz="0 0 -0.2017" rpy="0 0 0" />
    <parent link="wristYawLeft" />
    <child link="wristPitchLeft" />
    <axis xyz="0 1 0" />
    <limit lower="-0.96" upper="0.96" effort="6.4" velocity="5" />
  </joint>
  <link name="wristRollLeft">
    <inertial>
      <origin xyz="-0.00027229 0.00864497 -0.06627017" rpy="0 0 0" />
      <mass value="0.35749661" />
      <inertia ixx="0.00032014" ixy="0.00001166" ixz="-0.00000403" iyy="0.00042954" iyz="-0.00002167" izz="0.00018487" />
    </inertial>
    <visual>
      <origin xyz="0 0 0" rpy="0 0 0" />
      <geometry>
        <mesh filename="package://adamu_description/meshes/visual/wristRollLeft.dae" />
      </geometry>
      <material name="">
        <color rgba="0.752941176470588 0.752941176470588 0.752941176470588 1" />
      </material>
    </visual>
    <collision>
      <origin xyz="0 0 0" rpy="0 0 0" />
      <geometry>
        <mesh filename="package://adamu_description/meshes/collision/wristRollLeft.STL" />
      </geometry>
    </collision>
  </link>
  <joint name="wristRoll_Left" type="revolute">
    <origin xyz="0 0 0" rpy="0 0 0" />
    <parent link="wristPitchLeft" />
    <child link="wristRollLeft" />
    <axis xyz="1 0 0" />
    <limit lower="-0.96" upper="0.96" effort="6.4" velocity="5" />
  </joint>
  <link name="L_thumb_proximal_base">
    <inertial>
      <origin xyz="0.00431634 0.00026726 -0.00141885" rpy="0 0 0" />
      <mass value="0.00893190" />
      <inertia ixx="0.00000031" ixy="-0.00000008" ixz="-0.00000006" iyy="0.00000055" iyz="0.00000001" izz="0.00000046" />
    </inertial>
    <visual>
      <origin xyz="0 0 0" rpy="0 0 0" />
      <geometry>
        <mesh filename="package://adamu_description/meshes/visual/L_thumb_proximal_base.dae" />
      </geometry>
      <material name="">
        <color rgba="0.752941176470588 0.752941176470588 0.752941176470588 1" />
      </material>
    </visual>
    <collision>
      <origin xyz="0 0 0" rpy="0 0 0" />
      <geometry>
        <mesh filename="package://adamu_description/meshes/collision/L_thumb_proximal_base.STL" />
      </geometry>
    </collision>
  </link>
  <joint name="L_thumb_MCP_joint1" type="revolute">
    <origin xyz="0.0245 -0.01 -0.047" rpy="0 0 0" />
    <parent link="wristRollLeft" />
    <child link="L_thumb_proximal_base" />
    <axis xyz="0 0 -1" />
    <limit lower="0" upper="1.1" effort="1" velocity="1" />
  </joint>
  <link name="L_thumb_proximal">
    <inertial>
      <origin xyz="0.02369693 0.00000000 -0.01467236" rpy="0 0 0" />
      <mass value="0.06158427" />
      <inertia ixx="0.00001171" ixy="0.00000000" ixz="-0.00000575" iyy="0.00002013" iyz="0.00000000" izz="0.00001139" />
    </inertial>
    <visual>
      <origin xyz="0 0 0" rpy="0 0 0" />
      <geometry>
        <mesh filename="package://adamu_description/meshes/visual/L_thumb_proximal.dae" />
      </geometry>
      <material name="">
        <color rgba="0.752941176470588 0.752941176470588 0.752941176470588 1" />
      </material>
    </visual>
    <collision>
      <origin xyz="0 0 0" rpy="0 0 0" />
      <geometry>
        <mesh filename="package://adamu_description/meshes/collision/L_thumb_proximal.STL" />
      </geometry>
    </collision>
  </link>
  <joint name="L_thumb_MCP_joint2" type="revolute">
    <origin xyz="0.011954 -0.0010497 0" rpy="0 0 -0.087585" />
    <parent link="L_thumb_proximal_base" />
    <child link="L_thumb_proximal" />
    <axis xyz="0 1 0" />
    <limit lower="0" upper="0.5" effort="1" velocity="1" />
  </joint>
  <link name="L_thumb_intermediate">
    <inertial>
      <origin xyz="0.00973134 0.00000000 -0.00266466" rpy="0 0 0" />
      <mass value="0.01538337" />
      <inertia ixx="0.00000142" ixy="0.00000000" ixz="-0.00000039" iyy="0.00000172" iyz="0.00000000" izz="0.00000100" />
    </inertial>
    <visual>
      <origin xyz="0 0 0" rpy="0 0 0" />
      <geometry>
        <mesh filename="package://adamu_description/meshes/visual/L_thumb_intermediate.dae" />
      </geometry>
      <material name="">
        <color rgba="0.752941176470588 0.752941176470588 0.752941176470588 1" />
      </material>
    </visual>
    <collision>
      <origin xyz="0 0 0" rpy="0 0 0" />
      <geometry>
        <mesh filename="package://adamu_description/meshes/collision/L_thumb_intermediate.STL" />
      </geometry>
    </collision>
  </link>
  <joint name="L_thumb_PIP_joint" type="revolute">
    <origin xyz="0.044289 0 -0.037663" rpy="0 0 0" />
    <parent link="L_thumb_proximal" />
    <child link="L_thumb_intermediate" />
    <axis xyz="0 1 0" />
    <limit lower="0" upper="1" effort="1" velocity="1" />
  </joint>
  <link name="L_thumb_distal">
    <inertial>
      <origin xyz="0.00714221 -0.00000154 -0.00689404" rpy="0 0 0" />
      <mass value="0.01043740" />
      <inertia ixx="0.00000076" ixy="0.00000000" ixz="-0.00000020" iyy="0.00000086" iyz="0.00000000" izz="0.00000052" />
    </inertial>
    <visual>
      <origin xyz="0 0 0" rpy="0 0 0" />
      <geometry>
        <mesh filename="package://adamu_description/meshes/visual/L_thumb_distal.dae" />
      </geometry>
      <material name="">
        <color rgba="0.752941176470588 0.752941176470588 0.752941176470588 1" />
      </material>
    </visual>
    <collision>
      <origin xyz="0 0 0" rpy="0 0 0" />
      <geometry>
        <mesh filename="package://adamu_description/meshes/collision/L_thumb_distal.STL" />
      </geometry>
    </collision>
  </link>
  <joint name="L_thumb_DIP_joint" type="revolute">
    <origin xyz="0.016468 0 -0.015461" rpy="0 0 0" />
    <parent link="L_thumb_intermediate" />
    <child link="L_thumb_distal" />
    <axis xyz="0 1 0" />
    <limit lower="0" upper="1.2" effort="1" velocity="1" />
  </joint>
  <link name="L_index_proximal">
    <inertial>
      <origin xyz="0.00000000 0.00199817 -0.01311708" rpy="0 0 0" />
      <mass value="0.01454111" />
      <inertia ixx="0.00000195" ixy="0.00000000" ixz="0.00000000" iyy="0.00000195" iyz="0.00000002" izz="0.00000054" />
    </inertial>
    <visual>
      <origin xyz="0 0 0" rpy="0 0 0" />
      <geometry>
        <mesh filename="package://adamu_description/meshes/visual/L_index_proximal.dae" />
      </geometry>
      <material name="">
        <color rgba="0.752941176470588 0.752941176470588 0.752941176470588 1" />
      </material>
    </visual>
    <collision>
      <origin xyz="0 0 0" rpy="0 0 0" />
      <geometry>
        <mesh filename="package://adamu_description/meshes/collision/L_index_proximal.STL" />
      </geometry>
    </collision>
  </link>
  <joint name="L_index_MCP_joint" type="revolute">
    <origin xyz="0.026942 0.0095 -0.11498" rpy="0 -0.05236 0" />
    <parent link="wristRollLeft" />
    <child link="L_index_proximal" />
    <axis xyz="-1 0 0" />
    <limit lower="0" upper="1.7" effort="1" velocity="1" />
  </joint>
  <link name="L_index_distal">
    <inertial>
      <origin xyz="0.00000000 0.00168954 -0.01536935" rpy="0 0 0" />
      <mass value="0.00905901" />
      <inertia ixx="0.00000173" ixy="0.00000000" ixz="0.00000000" iyy="0.00000168" iyz="0.00000025" izz="0.00000025" />
    </inertial>
    <visual>
      <origin xyz="0 0 0" rpy="0 0 0" />
      <geometry>
        <mesh filename="package://adamu_description/meshes/visual/L_index_distal.dae" />
      </geometry>
      <material name="">
        <color rgba="0.752941176470588 0.752941176470588 0.752941176470588 1" />
      </material>
    </visual>
    <collision>
      <origin xyz="0 0 0" rpy="0 0 0" />
      <geometry>
        <mesh filename="package://adamu_description/meshes/collision/L_index_distal.STL" />
      </geometry>
    </collision>
  </link>
  <joint name="L_index_DIP_joint" type="revolute">
    <origin xyz="0 -0.0011127 -0.031981" rpy="0 0 0" />
    <parent link="L_index_proximal" />
    <child link="L_index_distal" />
    <axis xyz="-1 0 0" />
    <limit lower="0" upper="1.6" effort="1" velocity="1" />
  </joint>
  <link name="L_middle_proximal">
    <inertial>
      <origin xyz="0.00000000 0.00115546 -0.01334192" rpy="0 0 0" />
      <mass value="0.01313099" />
      <inertia ixx="0.00000194" ixy="0.00000000" ixz="0.00000000" iyy="0.00000193" iyz="0.00000010" izz="0.00000054" />
    </inertial>
    <visual>
      <origin xyz="0 0 0" rpy="0 0 0" />
      <geometry>
        <mesh filename="package://adamu_description/meshes/visual/L_middle_proximal.dae" />
      </geometry>
      <material name="">
        <color rgba="0.752941176470588 0.752941176470588 0.752941176470588 1" />
      </material>
    </visual>
    <collision>
      <origin xyz="0 0 0" rpy="0 0 0" />
      <geometry>
        <mesh filename="package://adamu_description/meshes/collision/L_middle_proximal.STL" />
      </geometry>
    </collision>
  </link>
  <joint name="L_middle_MCP_joint" type="revolute">
    <origin xyz="0.008 0.0145 -0.128" rpy="0 0 0" />
    <parent link="wristRollLeft" />
    <child link="L_middle_proximal" />
    <axis xyz="-1 0 0" />
    <limit lower="0" upper="1.7" effort="1" velocity="1" />
  </joint>
  <link name="L_middle_distal">
    <inertial>
      <origin xyz="0.00000000 -0.00003933 -0.01546189" rpy="0 0 0" />
      <mass value="0.00905901" />
      <inertia ixx="0.00000173" ixy="0.00000000" ixz="0.00000000" iyy="0.00000161" iyz="0.00000040" izz="0.00000032" />
    </inertial>
    <visual>
      <origin xyz="0 0 0" rpy="0 0 0" />
      <geometry>
        <mesh filename="package://adamu_description/meshes/visual/L_middle_distal.dae" />
      </geometry>
      <material name="">
        <color rgba="0.752941176470588 0.752941176470588 0.752941176470588 1" />
      </material>
    </visual>
    <collision>
      <origin xyz="0 0 0" rpy="0 0 0" />
      <geometry>
        <mesh filename="package://adamu_description/meshes/collision/L_middle_distal.STL" />
      </geometry>
    </collision>
  </link>
  <joint name="L_middle_DIP_joint" type="revolute">
    <origin xyz="0 -0.0029374 -0.031865" rpy="0 0 0" />
    <parent link="L_middle_proximal" />
    <child link="L_middle_distal" />
    <axis xyz="-1 0 0" />
    <limit lower="0" upper="1.6" effort="1" velocity="1" />
  </joint>
  <link name="L_ring_proximal">
    <inertial>
      <origin xyz="-0.00000395 0.00199338 -0.01313108" rpy="0 0 0" />
      <mass value="0.01454111" />
      <inertia ixx="0.00000195" ixy="0.00000000" ixz="0.00000000" iyy="0.00000195" iyz="0.00000002" izz="0.00000054" />
    </inertial>
    <visual>
      <origin xyz="0 0 0" rpy="0 0 0" />
      <geometry>
        <mesh filename="package://adamu_description/meshes/visual/L_ring_proximal.dae" />
      </geometry>
      <material name="">
        <color rgba="0.752941176470588 0.752941176470588 0.752941176470588 1" />
      </material>
    </visual>
    <collision>
      <origin xyz="0 0 0" rpy="0 0 0" />
      <geometry>
        <mesh filename="package://adamu_description/meshes/collision/L_ring_proximal.STL" />
      </geometry>
    </collision>
  </link>
  <joint name="L_ring_MCP_joint" type="revolute">
    <origin xyz="-0.010942 0.0095 -0.11998" rpy="0 0.05236 0" />
    <parent link="wristRollLeft" />
    <child link="L_ring_proximal" />
    <axis xyz="-1 0 0" />
    <limit lower="0" upper="1.7" effort="1" velocity="1" />
  </joint>
  <link name="L_ring_distal">
    <inertial>
      <origin xyz="0.00000000 0.00168954 -0.01536935" rpy="0 0 0" />
      <mass value="0.00905901" />
      <inertia ixx="0.00000173" ixy="0.00000000" ixz="0.00000000" iyy="0.00000168" iyz="0.00000025" izz="0.00000025" />
    </inertial>
    <visual>
      <origin xyz="0 0 0" rpy="0 0 0" />
      <geometry>
        <mesh filename="package://adamu_description/meshes/visual/L_ring_distal.dae" />
      </geometry>
      <material name="">
        <color rgba="0.752941176470588 0.752941176470588 0.752941176470588 1" />
      </material>
    </visual>
    <collision>
      <origin xyz="0 0 0" rpy="0 0 0" />
      <geometry>
        <mesh filename="package://adamu_description/meshes/collision/L_ring_distal.STL" />
      </geometry>
    </collision>
  </link>
  <joint name="L_ring_DIP_joint" type="revolute">
    <origin xyz="0 -0.0011127 -0.031981" rpy="0 0 0" />
    <parent link="L_ring_proximal" />
    <child link="L_ring_distal" />
    <axis xyz="-1 0 0" />
    <limit lower="0" upper="1.6" effort="1" velocity="1" />
  </joint>
  <link name="L_pinky_proximal">
    <inertial>
      <origin xyz="0.00000000 0.00191043 -0.01322575" rpy="0 0 0" />
      <mass value="0.01313099" />
      <inertia ixx="0.00000194" ixy="0.00000000" ixz="0.00000000" iyy="0.00000194" iyz="0.00000002" izz="0.00000053" />
    </inertial>
    <visual>
      <origin xyz="0 0 0" rpy="0 0 0" />
      <geometry>
        <mesh filename="package://adamu_description/meshes/visual/L_pinky_proximal.dae" />
      </geometry>
      <material name="">
        <color rgba="0.752941176470588 0.752941176470588 0.752941176470588 1" />
      </material>
    </visual>
    <collision>
      <origin xyz="0 0 0" rpy="0 0 0" />
      <geometry>
        <mesh filename="package://adamu_description/meshes/collision/L_pinky_proximal.STL" />
      </geometry>
    </collision>
  </link>
  <joint name="L_pinky_MCP_joint" type="revolute">
    <origin xyz="-0.030194 0.0045 -0.11287" rpy="0 0.12217 0" />
    <parent link="wristRollLeft" />
    <child link="L_pinky_proximal" />
    <axis xyz="-1 0 0" />
    <limit lower="0" upper="1.7" effort="1" velocity="1" />
  </joint>
  <link name="L_pinky_distal">
    <inertial>
      <origin xyz="0.00000199 0.00260409 -0.01099907" rpy="0 0 0" />
      <mass value="0.00693901" />
      <inertia ixx="0.00000086" ixy="0.00000000" ixz="0.00000000" iyy="0.00000084" iyz="0.00000010" izz="0.00000016" />
    </inertial>
    <visual>
      <origin xyz="0 0 0" rpy="0 0 0" />
      <geometry>
        <mesh filename="package://adamu_description/meshes/visual/L_pinky_distal.dae" />
      </geometry>
      <material name="">
        <color rgba="0.752941176470588 0.752941176470588 0.752941176470588 1" />
      </material>
    </visual>
    <collision>
      <origin xyz="0 0 0" rpy="0 0 0" />
      <geometry>
        <mesh filename="package://adamu_description/meshes/collision/L_pinky_distal.STL" />
      </geometry>
    </collision>
  </link>
  <joint name="L_pinky_DIP_joint" type="revolute">
    <origin xyz="0 -0.0011127 -0.031981" rpy="0 0 0" />
    <parent link="L_pinky_proximal" />
    <child link="L_pinky_distal" />
    <axis xyz="-1 0 0" />
    <limit lower="0" upper="1.6" effort="1" velocity="1" />
  </joint>
  <link name="shoulderPitchRight">
    <inertial>
      <origin xyz="-0.00066946 -0.02639720 0.00000000" rpy="0 0 0" />
      <mass value="0.21653557" />
      <inertia ixx="0.00018644" ixy="0.00000226" ixz="0.00000000" iyy="0.00030720" iyz="0.00000000" izz="0.00036960" />
    </inertial>
    <visual>
      <origin xyz="0 0 0" rpy="0 0 0" />
      <geometry>
        <mesh filename="package://adamu_description/meshes/visual/shoulderPitchRight.dae" />
      </geometry>
      <material name="">
        <color rgba="1 1 1 1" />
      </material>
    </visual>
    <collision>
      <origin xyz="0 0 0" rpy="0 0 0" />
      <geometry>
        <mesh filename="package://adamu_description/meshes/collision/shoulderPitchRight.STL" />
      </geometry>
    </collision>
  </link>
  <joint name="shoulderPitch_Right" type="revolute">
    <origin xyz="0 -0.16049 0.25755" rpy="-0.34907 0 0" />
    <parent link="torso" />
    <child link="shoulderPitchRight" />
    <axis xyz="0 1 0" />
    <limit lower="-3.613" upper="2.042" effort="65" velocity="8" />
  </joint>
  <link name="shoulderRollRight">
    <inertial>
      <origin xyz="-0.03328246 -0.00733504 -0.00951107" rpy="0 0 0" />
      <mass value="0.74506856" />
      <inertia ixx="0.00079998" ixy="-0.00001091" ixz="-0.00000820" iyy="0.00063152" iyz="0.00020919" izz="0.00054051" />
    </inertial>
    <visual>
      <origin xyz="0 0 0" rpy="0 0 0" />
      <geometry>
        <mesh filename="package://adamu_description/meshes/visual/shoulderRollRight.dae" />
      </geometry>
      <material name="">
        <color rgba="1 1 1 1" />
      </material>
    </visual>
    <collision>
      <origin xyz="0 0 0" rpy="0 0 0" />
      <geometry>
        <mesh filename="package://adamu_description/meshes/collision/shoulderRollRight.STL" />
      </geometry>
    </collision>
  </link>
  <joint name="shoulderRoll_Right" type="revolute">
    <origin xyz="0.0335 -0.0435 0" rpy="0.34907 0 0" />
    <parent link="shoulderPitchRight" />
    <child link="shoulderRollRight" />
    <axis xyz="1 0 0" />
    <limit lower="-2.793" upper="0.628" effort="65" velocity="8" />
  </joint>
  <link name="shoulderYawRight">
    <inertial>
      <origin xyz="-0.00062061 0.00064886 -0.08117839" rpy="0 0 0" />
      <mass value="0.76530592" />
      <inertia ixx="0.00351024" ixy="0.00000027" ixz="0.00004930" iyy="0.00340001" iyz="-0.00006084" izz="0.00046370" />
    </inertial>
    <visual>
      <origin xyz="0 0 0" rpy="0 0 0" />
      <geometry>
        <mesh filename="package://adamu_description/meshes/visual/shoulderYawRight.dae" />
      </geometry>
      <material name="">
        <color rgba="1 1 1 1" />
      </material>
    </visual>
    <collision>
      <origin xyz="0 0 0" rpy="0 0 0" />
      <geometry>
        <mesh filename="package://adamu_description/meshes/collision/shoulderYawRight.STL" />
      </geometry>
    </collision>
  </link>
  <joint name="shoulderYaw_Right" type="revolute">
    <origin xyz="-0.0335 -0.034 -0.0585" rpy="0 0 0" />
    <parent link="shoulderRollRight" />
    <child link="shoulderYawRight" />
    <axis xyz="0 0 1" />
    <limit lower="-2.583" upper="2.583" effort="65" velocity="8" />
  </joint>
  <link name="elbowRight">
    <inertial>
      <origin xyz="-0.01368579 -0.02914250 -0.02351374" rpy="0 0 0" />
      <mass value="0.87761532" />
      <inertia ixx="0.00085104" ixy="-0.00000753" ixz="0.00024114" iyy="0.00099228" iyz="-0.00001472" izz="0.00055884" />
    </inertial>
    <visual>
      <origin xyz="0 0 0" rpy="0 0 0" />
      <geometry>
        <mesh filename="package://adamu_description/meshes/visual/elbowRight.dae" />
      </geometry>
      <material name="">
        <color rgba="0.752941176470588 0.752941176470588 0.752941176470588 1" />
      </material>
    </visual>
    <collision>
      <origin xyz="0 0 0" rpy="0 0 0" />
      <geometry>
        <mesh filename="package://adamu_description/meshes/collision/elbowRight.STL" />
      </geometry>
    </collision>
  </link>
  <joint name="elbow_Right" type="revolute">
    <origin xyz="0 0.0285 -0.20415" rpy="0 0 0" />
    <parent link="shoulderYawRight" />
    <child link="elbowRight" />
    <axis xyz="0 1 0" />
    <limit lower="-2.496" upper="0.209" effort="30" velocity="8" />
  </joint>
  <link name="wristYawRight">
    <inertial>
      <origin xyz="-0.00202981 -0.00013146 -0.09216894" rpy="0 0 0" />
      <mass value="0.95587832" />
      <inertia ixx="0.00256092" ixy="0.00000273" ixz="0.00003067" iyy="0.00250028" iyz="0.00002722" izz="0.00055059" />
    </inertial>
    <visual>
      <origin xyz="0 0 0" rpy="0 0 0" />
      <geometry>
        <mesh filename="package://adamu_description/meshes/visual/wristYawRight.dae" />
      </geometry>
      <material name="">
        <color rgba="0.752941176470588 0.752941176470588 0.752941176470588 1" />
      </material>
    </visual>
    <collision>
      <origin xyz="0 0 0" rpy="0 0 0" />
      <geometry>
        <mesh filename="package://adamu_description/meshes/collision/wristYawRight.STL" />
      </geometry>
    </collision>
  </link>
  <joint name="wristYaw_Right" type="revolute">
    <origin xyz="-0.025 -0.0285 -0.0729" rpy="0 0 0" />
    <parent link="elbowRight" />
    <child link="wristYawRight" />
    <axis xyz="0 0 1" />
    <limit lower="-2.67" upper="2.67" effort="6.4" velocity="5" />
  </joint>
  <link name="wristPitchRight">
    <inertial>
      <origin xyz="-0.00017580 0.00166098 -0.00002773" rpy="0 0 0" />
      <mass value="0.11963454" />
      <inertia ixx="0.00003359" ixy="0.00000002" ixz="0.00000000" iyy="0.00002690" iyz="-0.00000005" izz="0.00003977" />
    </inertial>
    <visual>
      <origin xyz="0 0 0" rpy="0 0 0" />
      <geometry>
        <mesh filename="package://adamu_description/meshes/visual/wristPitchRight.dae" />
      </geometry>
      <material name="">
        <color rgba="0.752941176470588 0.752941176470588 0.752941176470588 1" />
      </material>
    </visual>
    <collision>
      <origin xyz="0 0 0" rpy="0 0 0" />
      <geometry>
        <mesh filename="package://adamu_description/meshes/collision/wristPitchRight.STL" />
      </geometry>
    </collision>
  </link>
  <joint name="wristPitch_Right" type="revolute">
    <origin xyz="0 0 -0.2017" rpy="0 0 0" />
    <parent link="wristYawRight" />
    <child link="wristPitchRight" />
    <axis xyz="0 1 0" />
    <limit lower="-0.96" upper="0.96" effort="6.4" velocity="5" />
  </joint>
  <link name="wristRollRight">
    <inertial>
      <origin xyz="-0.00030616 -0.00861825 -0.06634429" rpy="0 0 0" />
      <mass value="0.35815530" />
      <inertia ixx="0.00032078" ixy="-0.00001180" ixz="-0.00000453" iyy="0.00043005" iyz="0.00002137" izz="0.00018497" />
    </inertial>
    <visual>
      <origin xyz="0 0 0" rpy="0 0 0" />
      <geometry>
        <mesh filename="package://adamu_description/meshes/visual/wristRollRight.dae" />
      </geometry>
      <material name="">
        <color rgba="0.752941176470588 0.752941176470588 0.752941176470588 1" />
      </material>
    </visual>
    <collision>
      <origin xyz="0 0 0" rpy="0 0 0" />
      <geometry>
        <mesh filename="package://adamu_description/meshes/collision/wristRollRight.STL" />
      </geometry>
    </collision>
  </link>
  <joint name="wristRoll_Right" type="revolute">
    <origin xyz="0 0 0" rpy="0 0 0" />
    <parent link="wristPitchRight" />
    <child link="wristRollRight" />
    <axis xyz="1 0 0" />
    <limit lower="-0.96" upper="0.96" effort="6.4" velocity="5" />
  </joint>
  <link name="R_thumb_proximal_base">
    <inertial>
      <origin xyz="0.00431634 -0.00026726 -0.00141884" rpy="0 0 0" />
      <mass value="0.00893190" />
      <inertia ixx="0.00000031" ixy="0.00000008" ixz="-0.00000006" iyy="0.00000055" iyz="-0.00000001" izz="0.00000046" />
    </inertial>
    <visual>
      <origin xyz="0 0 0" rpy="0 0 0" />
      <geometry>
        <mesh filename="package://adamu_description/meshes/visual/R_thumb_proximal_base.dae" />
      </geometry>
      <material name="">
        <color rgba="0.752941176470588 0.752941176470588 0.752941176470588 1" />
      </material>
    </visual>
    <collision>
      <origin xyz="0 0 0" rpy="0 0 0" />
      <geometry>
        <mesh filename="package://adamu_description/meshes/collision/R_thumb_proximal_base.STL" />
      </geometry>
    </collision>
  </link>
  <joint name="R_thumb_MCP_joint1" type="revolute">
    <origin xyz="0.0245 0.01 -0.047" rpy="0 0 0" />
    <parent link="wristRollRight" />
    <child link="R_thumb_proximal_base" />
    <axis xyz="0 0 1" />
    <limit lower="0" upper="1.1" effort="1" velocity="1" />
  </joint>
  <link name="R_thumb_proximal">
    <inertial>
      <origin xyz="0.02369685 0.00000000 -0.01467226" rpy="0 0 0" />
      <mass value="0.06158426" />
      <inertia ixx="0.00001171" ixy="0.00000000" ixz="-0.00000575" iyy="0.00002013" iyz="0.00000000" izz="0.00001139" />
    </inertial>
    <visual>
      <origin xyz="0 0 0" rpy="0 0 0" />
      <geometry>
        <mesh filename="package://adamu_description/meshes/visual/R_thumb_proximal.dae" />
      </geometry>
      <material name="">
        <color rgba="0.752941176470588 0.752941176470588 0.752941176470588 1" />
      </material>
    </visual>
    <collision>
      <origin xyz="0 0 0" rpy="0 0 0" />
      <geometry>
        <mesh filename="package://adamu_description/meshes/collision/R_thumb_proximal.STL" />
      </geometry>
    </collision>
  </link>
  <joint name="R_thumb_MCP_joint2" type="revolute">
    <origin xyz="0.011954 0.0010497 0" rpy="0 0 0.087585" />
    <parent link="R_thumb_proximal_base" />
    <child link="R_thumb_proximal" />
    <axis xyz="0 1 0" />
    <limit lower="0" upper="0.5" effort="1" velocity="1" />
  </joint>
  <link name="R_thumb_intermediate">
    <inertial>
      <origin xyz="0.00973134 0.00000000 -0.00266467" rpy="0 0 0" />
      <mass value="0.01538338" />
      <inertia ixx="0.00000142" ixy="0.00000000" ixz="-0.00000039" iyy="0.00000172" iyz="0.00000000" izz="0.00000100" />
    </inertial>
    <visual>
      <origin xyz="0 0 0" rpy="0 0 0" />
      <geometry>
        <mesh filename="package://adamu_description/meshes/visual/R_thumb_intermediate.dae" />
      </geometry>
      <material name="">
        <color rgba="0.752941176470588 0.752941176470588 0.752941176470588 1" />
      </material>
    </visual>
    <collision>
      <origin xyz="0 0 0" rpy="0 0 0" />
      <geometry>
        <mesh filename="package://adamu_description/meshes/collision/R_thumb_intermediate.STL" />
      </geometry>
    </collision>
  </link>
  <joint name="R_thumb_PIP_joint" type="revolute">
    <origin xyz="0.044289 0 -0.037663" rpy="0 0 0" />
    <parent link="R_thumb_proximal" />
    <child link="R_thumb_intermediate" />
    <axis xyz="0 1 0" />
    <limit lower="0" upper="1" effort="1" velocity="1" />
  </joint>
  <link name="R_thumb_distal">
    <inertial>
      <origin xyz="0.00714151 0.00000139 -0.00689413" rpy="0 0 0" />
      <mass value="0.01043741" />
      <inertia ixx="0.00000076" ixy="0.00000000" ixz="-0.00000020" iyy="0.00000086" iyz="0.00000000" izz="0.00000052" />
    </inertial>
    <visual>
      <origin xyz="0 0 0" rpy="0 0 0" />
      <geometry>
        <mesh filename="package://adamu_description/meshes/visual/R_thumb_distal.dae" />
      </geometry>
      <material name="">
        <color rgba="0.752941176470588 0.752941176470588 0.752941176470588 1" />
      </material>
    </visual>
    <collision>
      <origin xyz="0 0 0" rpy="0 0 0" />
      <geometry>
        <mesh filename="package://adamu_description/meshes/collision/R_thumb_distal.STL" />
      </geometry>
    </collision>
  </link>
  <joint name="R_thumb_DIP_joint" type="revolute">
    <origin xyz="0.016468 0 -0.015461" rpy="0 0 0" />
    <parent link="R_thumb_intermediate" />
    <child link="R_thumb_distal" />
    <axis xyz="0 1 0" />
    <limit lower="0" upper="1.2" effort="1" velocity="1" />
  </joint>
  <link name="R_index_proximal">
    <inertial>
      <origin xyz="0.00000000 -0.00199820 -0.01311710" rpy="0 0 0" />
      <mass value="0.01454119" />
      <inertia ixx="0.00000195" ixy="0.00000000" ixz="0.00000000" iyy="0.00000195" iyz="-0.00000002" izz="0.00000054" />
    </inertial>
    <visual>
      <origin xyz="0 0 0" rpy="0 0 0" />
      <geometry>
        <mesh filename="package://adamu_description/meshes/visual/R_index_proximal.dae" />
      </geometry>
      <material name="">
        <color rgba="0.752941176470588 0.752941176470588 0.752941176470588 1" />
      </material>
    </visual>
    <collision>
      <origin xyz="0 0 0" rpy="0 0 0" />
      <geometry>
        <mesh filename="package://adamu_description/meshes/collision/R_index_proximal.STL" />
      </geometry>
    </collision>
  </link>
  <joint name="R_index_MCP_joint" type="revolute">
    <origin xyz="0.026942 -0.0095 -0.11498" rpy="0 -0.05236 0" />
    <parent link="wristRollRight" />
    <child link="R_index_proximal" />
    <axis xyz="1 0 0" />
    <limit lower="0" upper="1.7" effort="1" velocity="1" />
  </joint>
  <link name="R_index_distal">
    <inertial>
      <origin xyz="0.00000000 -0.00168936 -0.01536965" rpy="0 0 0" />
      <mass value="0.00905901" />
      <inertia ixx="0.00000173" ixy="0.00000000" ixz="0.00000000" iyy="0.00000168" iyz="-0.00000025" izz="0.00000025" />
    </inertial>
    <visual>
      <origin xyz="0 0 0" rpy="0 0 0" />
      <geometry>
        <mesh filename="package://adamu_description/meshes/visual/R_index_distal.dae" />
      </geometry>
      <material name="">
        <color rgba="0.752941176470588 0.752941176470588 0.752941176470588 1" />
      </material>
    </visual>
    <collision>
      <origin xyz="0 0 0" rpy="0 0 0" />
      <geometry>
        <mesh filename="package://adamu_description/meshes/collision/R_index_distal.STL" />
      </geometry>
    </collision>
  </link>
  <joint name="R_index_DIP_joint" type="revolute">
    <origin xyz="0 0.0011127 -0.031981" rpy="0 0 0" />
    <parent link="R_index_proximal" />
    <child link="R_index_distal" />
    <axis xyz="1 0 0" />
    <limit lower="0" upper="1.6" effort="1" velocity="1" />
  </joint>
  <link name="R_middle_proximal">
    <inertial>
      <origin xyz="0.00000000 -0.00115549 -0.01334194" rpy="0 0 0" />
      <mass value="0.01313107" />
      <inertia ixx="0.00000194" ixy="0.00000000" ixz="0.00000000" iyy="0.00000193" iyz="-0.00000010" izz="0.00000054" />
    </inertial>
    <visual>
      <origin xyz="0 0 0" rpy="0 0 0" />
      <geometry>
        <mesh filename="package://adamu_description/meshes/visual/R_middle_proximal.dae" />
      </geometry>
      <material name="">
        <color rgba="0.752941176470588 0.752941176470588 0.752941176470588 1" />
      </material>
    </visual>
    <collision>
      <origin xyz="0 0 0" rpy="0 0 0" />
      <geometry>
        <mesh filename="package://adamu_description/meshes/collision/R_middle_proximal.STL" />
      </geometry>
    </collision>
  </link>
  <joint name="R_middle_MCP_joint" type="revolute">
    <origin xyz="0.008 -0.0145 -0.128" rpy="0 0 0" />
    <parent link="wristRollRight" />
    <child link="R_middle_proximal" />
    <axis xyz="1 0 0" />
    <limit lower="0" upper="1.7" effort="1" velocity="1" />
  </joint>
  <link name="R_middle_distal">
    <inertial>
      <origin xyz="0.00000000 0.00003955 -0.01546217" rpy="0 0 0" />
      <mass value="0.00905901" />
      <inertia ixx="0.00000173" ixy="0.00000000" ixz="0.00000000" iyy="0.00000161" iyz="-0.00000040" izz="0.00000032" />
    </inertial>
    <visual>
      <origin xyz="0 0 0" rpy="0 0 0" />
      <geometry>
        <mesh filename="package://adamu_description/meshes/visual/R_middle_distal.dae" />
      </geometry>
      <material name="">
        <color rgba="0.752941176470588 0.752941176470588 0.752941176470588 1" />
      </material>
    </visual>
    <collision>
      <origin xyz="0 0 0" rpy="0 0 0" />
      <geometry>
        <mesh filename="package://adamu_description/meshes/collision/R_middle_distal.STL" />
      </geometry>
    </collision>
  </link>
  <joint name="R_middle_DIP_joint" type="revolute">
    <origin xyz="0 0.0029374 -0.031865" rpy="0 0 0" />
    <parent link="R_middle_proximal" />
    <child link="R_middle_distal" />
    <axis xyz="1 0 0" />
    <limit lower="0" upper="1.6" effort="1" velocity="1" />
  </joint>
  <link name="R_ring_proximal">
    <inertial>
      <origin xyz="0.00000000 -0.00199820 -0.01311710" rpy="0 0 0" />
      <mass value="0.01454119" />
      <inertia ixx="0.00000195" ixy="0.00000000" ixz="0.00000000" iyy="0.00000195" iyz="-0.00000002" izz="0.00000054" />
    </inertial>
    <visual>
      <origin xyz="0 0 0" rpy="0 0 0" />
      <geometry>
        <mesh filename="package://adamu_description/meshes/visual/R_ring_proximal.dae" />
      </geometry>
      <material name="">
        <color rgba="0.752941176470588 0.752941176470588 0.752941176470588 1" />
      </material>
    </visual>
    <collision>
      <origin xyz="0 0 0" rpy="0 0 0" />
      <geometry>
        <mesh filename="package://adamu_description/meshes/collision/R_ring_proximal.STL" />
      </geometry>
    </collision>
  </link>
  <joint name="R_ring_MCP_joint" type="revolute">
    <origin xyz="-0.010942 -0.0095 -0.11998" rpy="0 0.05236 0" />
    <parent link="wristRollRight" />
    <child link="R_ring_proximal" />
    <axis xyz="1 0 0" />
    <limit lower="0" upper="1.7" effort="1" velocity="1" />
  </joint>
  <link name="R_ring_distal">
    <inertial>
      <origin xyz="0.00000000 -0.00168936 -0.01536965" rpy="0 0 0" />
      <mass value="0.00905901" />
      <inertia ixx="0.00000173" ixy="0.00000000" ixz="0.00000000" iyy="0.00000168" iyz="-0.00000025" izz="0.00000025" />
    </inertial>
    <visual>
      <origin xyz="0 0 0" rpy="0 0 0" />
      <geometry>
        <mesh filename="package://adamu_description/meshes/visual/R_ring_distal.dae" />
      </geometry>
      <material name="">
        <color rgba="0.752941176470588 0.752941176470588 0.752941176470588 1" />
      </material>
    </visual>
    <collision>
      <origin xyz="0 0 0" rpy="0 0 0" />
      <geometry>
        <mesh filename="package://adamu_description/meshes/collision/R_ring_distal.STL" />
      </geometry>
    </collision>
  </link>
  <joint name="R_ring_DIP_joint" type="revolute">
    <origin xyz="0 0.0011127 -0.031981" rpy="0 0 0" />
    <parent link="R_ring_proximal" />
    <child link="R_ring_distal" />
    <axis xyz="1 0 0" />
    <limit lower="0" upper="1.6" effort="1" velocity="1" />
  </joint>
  <link name="R_pinky_proximal">
    <inertial>
      <origin xyz="0.00000000 -0.00191046 -0.01322577" rpy="0 0 0" />
      <mass value="0.01313107" />
      <inertia ixx="0.00000194" ixy="0.00000000" ixz="0.00000000" iyy="0.00000194" iyz="-0.00000002" izz="0.00000053" />
    </inertial>
    <visual>
      <origin xyz="0 0 0" rpy="0 0 0" />
      <geometry>
        <mesh filename="package://adamu_description/meshes/visual/R_pinky_proximal.dae" />
      </geometry>
      <material name="">
        <color rgba="0.752941176470588 0.752941176470588 0.752941176470588 1" />
      </material>
    </visual>
    <collision>
      <origin xyz="0 0 0" rpy="0 0 0" />
      <geometry>
        <mesh filename="package://adamu_description/meshes/collision/R_pinky_proximal.STL" />
      </geometry>
    </collision>
  </link>
  <joint name="R_pinky_MCP_joint" type="revolute">
    <origin xyz="-0.030194 -0.0045 -0.11287" rpy="0 0.12217 0" />
    <parent link="wristRollRight" />
    <child link="R_pinky_proximal" />
    <axis xyz="1 0 0" />
    <limit lower="0" upper="1.7" effort="1" velocity="1" />
  </joint>
  <link name="R_pinky_distal">
    <inertial>
      <origin xyz="0.00000201 -0.00260417 -0.01099890" rpy="0 0 0" />
      <mass value="0.00693901" />
      <inertia ixx="0.00000086" ixy="0.00000000" ixz="0.00000000" iyy="0.00000084" iyz="-0.00000010" izz="0.00000016" />
    </inertial>
    <visual>
      <origin xyz="0 0 0" rpy="0 0 0" />
      <geometry>
        <mesh filename="package://adamu_description/meshes/visual/R_pinky_distal.dae" />
      </geometry>
      <material name="">
        <color rgba="0.752941176470588 0.752941176470588 0.752941176470588 1" />
      </material>
    </visual>
    <collision>
      <origin xyz="0 0 0" rpy="0 0 0" />
      <geometry>
        <mesh filename="package://adamu_description/meshes/collision/R_pinky_distal.STL" />
      </geometry>
    </collision>
  </link>
  <joint name="R_pinky_DIP_joint" type="revolute">
    <origin xyz="0 0.0011127 -0.031981" rpy="0 0 0" />
    <parent link="R_pinky_proximal" />
    <child link="R_pinky_distal" />
    <axis xyz="1 0 0" />
    <limit lower="0" upper="1.6" effort="1" velocity="1" />
  </joint>
  <link name="neckYaw">
    <inertial>
      <origin xyz="0.02291662 -0.00099716 0.10018738" rpy="0 0 0" />
      <mass value="0.41242410" />
      <inertia ixx="0.00122006" ixy="-0.00000369" ixz="0.00026238" iyy="0.00129324" iyz="-0.00001218" izz="0.00019172" />
    </inertial>
    <visual>
      <origin xyz="0 0 0" rpy="0 0 0" />
      <geometry>
        <mesh filename="package://adamu_description/meshes/visual/neckYaw.dae" />
      </geometry>
      <material name="">
        <color rgba="1 1 1 1" />
      </material>
    </visual>
    <collision>
      <origin xyz="0 0 0" rpy="0 0 0" />
      <geometry>
        <mesh filename="package://adamu_description/meshes/collision/neckYaw.STL" />
      </geometry>
    </collision>
  </link>
  <joint name="neckYaw" type="revolute">
    <origin xyz="-0.013 0 0.29855" rpy="0 0 0" />
    <parent link="torso" />
    <child link="neckYaw" />
    <axis xyz="0 0 1" />
    <limit lower="-1.571" upper="1.571" effort="6.4" velocity="5" />
  </joint>
  <link name="neckPitch">
    <inertial>
      <origin xyz="0.01790361 -0.02046619 0.04596285" rpy="0 0 0" />
      <mass value="0.99740875" />
      <inertia ixx="0.00264869" ixy="0.00000400" ixz="-0.00057282" iyy="0.00354694" iyz="-0.00000544" izz="0.00348523" />
    </inertial>
    <visual>
      <origin xyz="0 0 0" rpy="0 0 0" />
      <geometry>
        <mesh filename="package://adamu_description/meshes/visual/neckPitch.dae" />
      </geometry>
      <material name="">
        <color rgba="1 1 1 1" />
      </material>
    </visual>
    <collision>
      <origin xyz="0 0 0" rpy="0 0 0" />
      <geometry>
        <mesh filename="package://adamu_description/meshes/collision/neckPitch.STL" />
      </geometry>
    </collision>
  </link>
  <joint name="neckPitch" type="revolute">
    <origin xyz="0.0316 0.02 0.14595" rpy="0 0 0" />
    <parent link="neckYaw" />
    <child link="neckPitch" />
    <axis xyz="0 1 0" />
    <limit lower="-0.873" upper="0.873" effort="6.4" velocity="5" />
  </joint>


  <link name="left_hand_tcp"/>
  <joint name="left_wrist_to_tcp" type="fixed">
    <parent link="left_hand_fts" />
    <child link="left_hand_tcp" />
    <origin xyz="0.0 0.0 0.0" rpy="0 0 0" />
  </joint>

  <link name="right_hand_tcp"/>
  <joint name="right_wrist_to_tcp" type="fixed">
    <parent link="right_hand_fts" />
      <child link="right_hand_tcp" />
      <origin xyz="0.0 0.0 0.0" rpy="0 0 0" />
  </joint>

  <link name="left_hand_fts"/>
  <joint name="left_wrist_to_fts" type="fixed">
    <parent link="wristRollLeft" />
    <child link="left_hand_fts" />
    <origin xyz="0.0 0.0 -0.1" rpy="0 0 0" />
  </joint>

  <link name="right_hand_fts"/>
  <joint name="right_wrist_to_fts" type="fixed">
    <parent link="wristRollRight" />
    <child link="right_hand_fts" />
    <origin xyz="0.0 0.0 -0.1" rpy="0 0 0" />
  </joint>
</robot>  
